Workbook

Sheet PARÁMETROS
A1: PROYECTO TERRASENSE — SISTEMA IoT DE DIAGNÓSTICO AGRONÓMICO
A2: Equipo: Alan Escobar - Alvaro Villenassssssss
A4: PARÁMETROS GENERALES | B4: Valor | C4: Notas
A5: Tipo de cambio USD → CLP | B5: 915 | C5: BCCh, referencia 18-ago-2026
A6: Lote inicial (unidades beta) | B6: 10 | C6: Preserie de validación
A7: Unidades Año 1 | B7: 200 | C7: 🔧 AJUSTABLE: unidades Año 1
A8: Unidades Año 2 | B8: 350 | C8: 🔧 AJUSTABLE: unidades Año 2
A9: Unidades Año 3 | B9: 500 | C9: 🔧 AJUSTABLE: unidades Año 3
A10: Unidades Año 4 | B10: 650 | C10: 🔧 AJUSTABLE: unidades Año 4
A11: Unidades Año 5 | B11: 850 | C11: 🔧 AJUSTABLE: unidades Año 5
A12: Tasa de descuento (r) | B12: 0.2 | C12: 🔧 AJUSTABLE: tasa de descuento
A13: Tasa impuesto a la renta | B13: 0.25 | C13: 🔧 AJUSTABLE: impuesto renta
A14: Margen de ganancia objetivo | B14: 0.56535177 | C14: 🔧 AJUSTABLE: margen bruto sobre precio neto
A16: FINANCIAMIENTO BANCARIO | B16: Valor | C16: Notas
A17: Monto financiado | B17: ='AMORTIZACIÓN BANCARIA'!B3 -> 15000000 | C17: CLP: crédito largo + línea corta
A18: Tasa anual | B18: ='AMORTIZACIÓN BANCARIA'!E4 -> 0.1 | C18: Crédito PYME largo plazo; línea corta 23%
A19: Tasa mensual | B19: =B18/12 -> 0.0083333333 | C19: Referencia del crédito largo
A20: Plazo | B20: ='AMORTIZACIÓN BANCARIA'!B6 -> 60 | C20: 5 años
A21: Cuota mensual fija | B21: ='AMORTIZACIÓN BANCARIA'!B7 -> 212470 | C21: Referencia: crédito largo de $10.000.000
A22: Total a pagar | B22: ='AMORTIZACIÓN BANCARIA'!B8 -> 18898200 | C22: Capital e intereses de ambas deudas
A23: Total intereses pagados | B23: ='AMORTIZACIÓN BANCARIA'!B9 -> 3898200 | C23: $2.040.720 largo + $1.150.000 corto
A25: ="EXPLICACIÓN TASA DE DESCUENTO "&TEXT(B12,"0%")&" La tasa representa la rentabilidad mínima exigida por la pauta. El modelo usa horizonte de 5 años, precio neto de IVA y costos en CLP; los supuestos provienen de la Sección XII del README del proyecto." -> EXPLICACIÓN TASA DE DESCUENTO 20% La tasa representa la rentabilidad mínima exigida por la pauta. El modelo usa horizonte de 5 años, precio neto de IVA y costos en CLP; los supuestos provienen de la Sección XII del README del proyecto.

Sheet BOM - COMPONENTES
A1: LISTA DE MATERIALES (BOM) - TERRASENSE
A2: Costo unitario validado | USD 1 = CLP 915
A4: ID | B4: Categoría | C4: Componente | D4: Referencia | E4: Encapsulado | F4: Cant/Placa | G4: Cant Compra | H4: P.Unit USD | I4: P.Unit CLP | J4: Total Compra CLP | K4: Costo/Unidad CLP | L4: Distribuidor
A5: 1 | B5: Electrónica | C5: ESP32-WROOM-32E | D5: U1 | E5: Según BOM | F5: 1 | G5: 1 | H5: 3.020765 | I5: =H5*PARÁMETROS!$B$5 -> 2764 | J5: =I5*G5 -> 2764 | K5: =ROUND(I5*F5,0) -> 2764 | L5: PCB/BOM_TerraSense.xlsx
A6: 2 | B6: Electrónica | C6: CH340C USB-Serial | D6: U2 | E6: Según BOM | F6: 1 | G6: 1 | H6: 0.33005464 | I6: =H6*PARÁMETROS!$B$5 -> 302 | J6: =I6*G6 -> 302 | K6: =ROUND(I6*F6,0) -> 302 | L6: PCB/BOM_TerraSense.xlsx
A7: 3 | B7: Electrónica | C7: MAX3485 RS-485 | D7: U3 | E7: Según BOM | F7: 1 | G7: 1 | H7: 0.1420765 | I7: =H7*PARÁMETROS!$B$5 -> 130 | J7: =I7*G7 -> 130 | K7: =ROUND(I7*F7,0) -> 130 | L7: PCB/BOM_TerraSense.xlsx
A8: 4 | B8: Electrónica | C8: BME280 | D8: U4 | E8: Según BOM | F8: 1 | G8: 1 | H8: 2.3595628 | I8: =H8*PARÁMETROS!$B$5 -> 2159 | J8: =I8*G8 -> 2159 | K8: =ROUND(I8*F8,0) -> 2159 | L8: PCB/BOM_TerraSense.xlsx
A9: 5 | B9: Electrónica | C9: MT3608 elevador | D9: U5 | E9: Según BOM | F9: 1 | G9: 1 | H9: 0.075409836 | I9: =H9*PARÁMETROS!$B$5 -> 69 | J9: =I9*G9 -> 69 | K9: =ROUND(I9*F9,0) -> 69 | L9: PCB/BOM_TerraSense.xlsx
A10: 6 | B10: Electrónica | C10: TP4056 cargador | D10: U6 | E10: Según BOM | F10: 1 | G10: 1 | H10: 0.093989071 | I10: =H10*PARÁMETROS!$B$5 -> 86 | J10: =I10*G10 -> 86 | K10: =ROUND(I10*F10,0) -> 86 | L10: PCB/BOM_TerraSense.xlsx
A11: 7 | B11: Electrónica | C11: AP2112K-3.3 LDO | D11: U7 | E11: Según BOM | F11: 1 | G11: 1 | H11: 0.1136612 | I11: =H11*PARÁMETROS!$B$5 -> 104 | J11: =I11*G11 -> 104 | K11: =ROUND(I11*F11,0) -> 104 | L11: PCB/BOM_TerraSense.xlsx
A12: 8 | B12: Electrónica | C12: AO3401A P-MOSFET | D12: Q1 | E12: Según BOM | F12: 1 | G12: 1 | H12: 0.018579235 | I12: =H12*PARÁMETROS!$B$5 -> 17 | J12: =I12*G12 -> 17 | K12: =ROUND(I12*F12,0) -> 17 | L12: PCB/BOM_TerraSense.xlsx
A13: 9 | B13: Electrónica | C13: MMBT3904 NPN | D13: Q2-Q3 | E13: Según BOM | F13: 2 | G13: 2 | H13: 0.019125683 | I13: =H13*PARÁMETROS!$B$5 -> 17.5 | J13: =I13*G13 -> 35 | K13: =ROUND(I13*F13,0) -> 35 | L13: PCB/BOM_TerraSense.xlsx
A14: 10 | B14: Electrónica | C14: Inductor 22µH | D14: L1 | E14: Según BOM | F14: 1 | G14: 1 | H14: 0.18907104 | I14: =H14*PARÁMETROS!$B$5 -> 173 | J14: =I14*G14 -> 173 | K14: =ROUND(I14*F14,0) -> 173 | L14: PCB/BOM_TerraSense.xlsx
A15: 11 | B15: Electrónica | C15: SS34 Schottky | D15: D3 | E15: Según BOM | F15: 1 | G15: 1 | H15: 0.046994536 | I15: =H15*PARÁMETROS!$B$5 -> 43 | J15: =I15*G15 -> 43 | K15: =ROUND(I15*F15,0) -> 43 | L15: PCB/BOM_TerraSense.xlsx
A16: 12 | B16: Electrónica | C16: TVS dual ESD | D16: D4 | E16: Según BOM | F16: 1 | G16: 1 | H16: 0.075409836 | I16: =H16*PARÁMETROS!$B$5 -> 69 | J16: =I16*G16 -> 69 | K16: =ROUND(I16*F16,0) -> 69 | L16: PCB/BOM_TerraSense.xlsx
... A28: 24 | B28: Integración | C28: Sonda principal | D28: Sonda 7-en-1 RS-485 inox 316L | E28: N/A | F28: 1 | G28: 1 | H28: 52.459016 | I28: =H28*PARÁMETROS!$B$5 -> 48000 | J28: =I28*G28 -> 48000 | K28: =ROUND(I28*F28,0) -> 48000 | L28: README §XII.2.1
J30: TOTAL COMPRA | K30: =ROUND(SUM(J5:J28),0) -> 70656
J31: Costo componentes / unidad | K31: =SUM(K5:K28) -> 70656
J32: Herramientas lab | K32: ='EQUIPAMIENTO LAB'!D22 -> 4910000

Sheet EQUIPAMIENTO LAB
A1: EQUIPAMIENTO DE LABORATORIO TERRASENSE
A3: DISPONIBLES (sin costo adicional)
A4: ✅ Espacio de trabajo en casa de socios
A5: ✅ Internet base
A6: ✅ Herramienta manual básica
A7: ✅ Teléfonos de prueba
A8: ✅ Software y repositorio
A10: A ADQUIRIR!!!
B11: Instrumento | C11: Marca / Modelo | D11: Precio CLP | E11: Prioridad
B12: Impresora 3D FDM principal | C12: Cámara cerrada | D12: 900000 | E12: 🔴 Alta
B13: Impresora 3D FDM secundaria | C13: Redundancia | D13: 450000 | E13: 🟡 Media
B14: Secador y almacenamiento filamento | C14: Estanco | D14: 80000 | E14: 🟡 Media
B15: Soldadura, aire caliente y microscopio | C15: Banco SMD | D15: 240000 | E15: 🔴 Alta
B16: Fuente programable + multímetro banco | C16: Banco eléctrico | D16: 250000 | E16: 🔴 Alta
B17: Osciloscopio 100 MHz 2 canales | C17: Instrumentación | D17: 400000 | E17: 🔴 Alta
B18: Analizador, programador y sonda µA | C18: Instrumentación | D18: 160000 | E18: 🟡 Media
B19: Banco IP67 + patrón pH/EC | C19: Validación | D19: 530000 | E19: 🔴 Alta
B20: 2 notebooks y puestos desarrollo | C20: Uno por socio | D20: 1600000 | E20: 🔴 Alta
B21: Mobiliario y almacenamiento | C21: Taller | D21: 300000 | E21: 🟡 Media
B22: TOTAL | D22: =SUM(D12:D21) -> 4910000

Sheet INVERSIÓN INICIAL
A1: INVERSIÓN INICIAL - TERRASENSE
A3: COMPONENTE | B3: Costo (CLP) | C3: Notas
A4: A. Constitución SpA y trámites | B4: 150000 | C4: Activo nominal
A5: B. Ensayos agronómicos | B5: 900000 | C5: 30 muestras
A6: C. Ensayos IP67 y EMC | B6: 1500000 | C6: Externos
A7: D. Sitio web, marca y material | B7: 450000 | C7: Comercial
A8: E. Patrones de calibración | B8: 120000 | C8: pH y EC
A9: F. Herramienta menor y consumibles | B9: 150000 | C9: Taller
A10: G. Lote piloto de validación | B10: 913090 | C10: 10 uds × $91.309
A11: H. Capital de trabajo | B11: 14806910 | C11: 3 meses + primer lote 100 uds
A12: I. Equipamiento de laboratorio | B12: 4910000 | C12: Ver hoja EQUIPAMIENTO LAB
A13: J. Otros | B13: 0 | C13: Sin partidas adicionales
A14: SUBTOTAL | B14: =SUM(B4:B13) -> 23900000
A15: K. Contingencia / imprevistos | B15: =0 -> 0
A16: TOTAL INVERSIÓN INICIAL | B16: =SUM(B14:B15) -> 23900000
A18: FINANCIADO CON PRÉSTAMO BANCARIO | B18: ='AMORTIZACIÓN BANCARIA'!B3 -> 15000000 | C18: $10MM largo + $5MM corto
A19: APORTE PROPIO | B19: =B16-B18 -> 8900000 | C19: 2 socios: $4.450.000 cada uno
A21: HORAS DE TRABAJO (sin costo monetario) | B21: H/Unid | C21: # Unid | D21: Total Horas
A22: Ensamblado y QA por unidad | B22: 1.5 | C22: 200 | D22: =B22*C22 -> 300
A23: Programación y flasheo firmware | B23: 0.5 | C23: 200 | D23: =B23*C23 -> 100
A24: Testing y calibración | B24: 0.5 | C24: 200 | D24: =B24*C24 -> 100
A25: Embalaje y despacho | B25: 0.25 | C25: 200 | D25: =B25*C25 -> 50
A26: Desarrollo App y Web (total) | B26: 600 | C26: 1 | D26: =B26*C26 -> 600
A27: Gestión / Administración / Compras | B27: 300 | C27: 1 | D27: =B27*C27 -> 300
A28: TOTAL HORAS (2 socios) | B28: 0 | C28: 0 | D28: =SUM(D22:D27) -> 1450
A29: Horas por socio | B29: 0 | C29: 0 | D29: =D28/2 -> 725

Sheet AMORTIZACIÓN BANCARIA
A1: TABLA DE AMORTIZACIÓN BANCARIA - TERRASENSE
A3: Monto préstamo | B3: =E3+E5 -> 15000000 | C3: CLP total | D3: Crédito largo | E3: 10000000
A4: Tasa anual | B4: =E4 -> 0.1 | C4: Crédito largo; línea corta en E6 | D4: Tasa largo | E4: 0.1
A5: Tasa mensual | B5: =E4/12 -> 0.0083333333 | C5: Crédito largo | D5: Línea corta | E5: 5000000
A6: Plazo | B6: =60 -> 60 | C6: Meses crédito largo | D6: Tasa corta | E6: 0.23
A7: Cuota mensual fija | B7: =ROUND(-PMT(E4/12,B6,E3),0) -> 212470 | C7: Cuota crédito largo | D7: Saldo fin Año 4 | E7: =ROUND(MAX(0,$E$3*(1+$B$5)^48-$B$7*((1+$B$5)^48-1)/$B$5),0) -> 2416773
A8: Total a pagar | B8: =B7*B6+E5*(1+E6) -> 18898200 | C8: Ambas deudas | D8: Saldo fin Año 5 | E8: =0 -> 0
A9: Total intereses | B9: =B8-B3 -> 3898200 | C9: Ambas deudas | D9: Pago anual largo | E9: =$B$7*12 -> 2549640
A11: RESUMEN ANUAL
A12: Año | B12: Cuotas pagadas | C12: Capital amortizado | D12: Intereses pagados | E12: Saldo restante
A13: 1 | B13: =ROUND($E$9+$E$5*(1+$E$6),0) -> 8699640 | C13: =ROUND($E$3+$E$5-E13,0) -> 6622676 | D13: =B13-C13 -> 2076964 | E13: =ROUND(MAX(0,$E$3*(1+$B$5)^12-$B$7*((1+$B$5)^12-1)/$B$5),0) -> 8377324
A14: 2 | B14: =$E$9 -> 2549640 | C14: =E13-E14 -> 1792591 | D14: =B14-C14 -> 757049 | E14: =ROUND(MAX(0,E13*(1+$B$5)^12-$B$7*((1+$B$5)^12-1)/$B$5),0) -> 6584733
A15: 3 | B15: =$E$9 -> 2549640 | C15: =E14-E15 -> 1980299 | D15: =B15-C15 -> 569341 | E15: =ROUND(MAX(0,E14*(1+$B$5)^12-$B$7*((1+$B$5)^12-1)/$B$5),0) -> 4604434
A16: Años 4-5 | B16: =$E$9*2 -> 5099280 | C16: =E15-$E$8 -> 4604434 | D16: =B16-C16 -> 494846 | E16: =$E$8 -> 0
A18: TABLA MENSUAL — CRÉDITO LARGO (MESES 1–36 DE 60)
A19: Mes | B19: Cuota (CLP) | C19: Capital (CLP) | D19: Intereses (CLP) | E19: Saldo (CLP)
A20: 1 | B20: =$B$7 -> 212470 | C20: =ROUND(B20-D20,0) -> 129137 | D20: =ROUND($E$3*$B$5,0) -> 83333 | E20: =ROUND($E$3-C20,0) -> 9870863
A21: 2 | B21: =$B$7 -> 212470 | C21: =ROUND(B21-D21,0) -> 130213 | D21: =ROUND(E20*$B$5,0) -> 82257 | E21: =ROUND(E20-C21,0) -> 9740650
A22: 3 | B22: =$B$7 -> 212470 | C22: =ROUND(B22-D22,0) -> 131298 | D22: =ROUND(E21*$B$5,0) -> 81172 | E22: =ROUND(E21-C22,0) -> 9609352
A23: 4 | B23: =$B$7 -> 212470 | C23: =ROUND(B23-D23,0) -> 132392 | D23: =ROUND(E22*$B$5,0) -> 80078 | E23: =ROUND(E22-C23,0) -> 9476960
A24: 5 | B24: =$B$7 -> 212470 | C24: =ROUND(B24-D24,0) -> 133495 | D24: =ROUND(E23*$B$5,0) -> 78975 | E24: =ROUND(E23-C24,0) -> 9343465
A25: 6 | B25: =$B$7 -> 212470 | C25: =ROUND(B25-D25,0) -> 134608 | D25: =ROUND(E24*$B$5,0) -> 77862 | E25: =ROUND(E24-C25,0) -> 9208857
A26: 7 | B26: =$B$7 -> 212470 | C26: =ROUND(B26-D26,0) -> 135730 | D26: =ROUND(E25*$B$5,0) -> 76740 | E26: =ROUND(E25-C26,0) -> 9073127
A27: 8 | B27: =$B$7 -> 212470 | C27: =ROUND(B27-D27,0) -> 136861 | D27: =ROUND(E26*$B$5,0) -> 75609 | E27: =ROUND(E26-C27,0) -> 8936266
A28: 9 | B28: =$B$7 -> 212470 | C28: =ROUND(B28-D28,0) -> 138001 | D28: =ROUND(E27*$B$5,0) -> 74469 | E28: =ROUND(E27-C28,0) -> 8798265
A29: 10 | B29: =$B$7 -> 212470 | C29: =ROUND(B29-D29,0) -> 139151 | D29: =ROUND(E28*$B$5,0) -> 73319 | E29: =ROUND(E28-C29,0) -> 8659114
A30: 11 | B30: =$B$7 -> 212470 | C30: =ROUND(B30-D30,0) -> 140311 | D30: =ROUND(E29*$B$5,0) -> 72159 | E30: =ROUND(E29-C30,0) -> 8518803
A31: 12 | B31: =$B$7 -> 212470 | C31: =ROUND(B31-D31,0) -> 141480 | D31: =ROUND(E30*$B$5,0) -> 70990 | E31: =ROUND(E30-C31,0) -> 8377323
A32: 13 | B32: =$B$7 -> 212470 | C32: =ROUND(B32-D32,0) -> 142659 | D32: =ROUND(E31*$B$5,0) -> 69811 | E32: =ROUND(E31-C32,0) -> 8234664
... A55: 36 | B55: =$B$7 -> 212470 | C55: =ROUND(B55-D55,0) -> 172661 | D55: =ROUND(E54*$B$5,0) -> 39809 | E55: =ROUND(E54-C55,0) -> 4604432

Sheet PROYECCIÓN + VAN
A1: PROYECCIÓN FINANCIERA A 5 AÑOS - TERRASENSE
A2: ="Tasa descuento "&TEXT(B5,"0%")&" | Precio $"&TEXT(B7,"#,##0")&" IVA incl. | Inversión $"&TEXT('INVERSIÓN INICIAL'!B16,"#,##0") -> Tasa descuento 20% | Precio $249990,0 IVA incl. | Inversión $23900000,0
A4: SUPUESTOS
A5: Tasa de descuento (r) | B5: =PARÁMETROS!B12 -> 0.2 | C5: Pauta de evaluación
A6: Tasa impuesto renta | B6: =PARÁMETROS!B13 -> 0.25 | C6: Pro Pyme General
A7: PVP | B7: ='COSTO x UNIDAD'!B15 -> 249990 | C7: IVA incluido
A8: Precio neto (sin IVA) | B8: ='COSTO x UNIDAD'!B17 -> 210076 | C8: Ingreso real por venta
A9: Costo variable / unidad | B9: ='COSTO x UNIDAD'!B10 -> 91309 | C9: Año 1
A10: Gastos fijos | B10: 0 | C10: 16946852 | D10: 28990000 | E10: 55440000 | F10: 66470000 | G10: 83520000
A11: ESTADO DE RESULTADOS | B11: AÑO 0 | C11: AÑO 1 | D11: AÑO 2 | E11: AÑO 3 | F11: AÑO 4 | G11: AÑO 5
A12: Unidades | B12: =PARÁMETROS!B6 -> 10 | C12: =PARÁMETROS!B7 -> 200 | D12: =PARÁMETROS!B8 -> 350 | E12: =PARÁMETROS!B9 -> 500 | F12: =PARÁMETROS!B10 -> 650 | G12: =PARÁMETROS!B11 -> 850
A13: (+) Ingresos netos (CLP) | B13: =0 -> 0 | C13: =C12*$B$8 -> 42015200 | D13: =D12*$B$8 -> 73526600 | E13: =E12*$B$8 -> 105038000 | F13: =F12*$B$8 -> 136549400 | G13: =G12*$B$8 -> 178564600
A14: (-) Costos variables | B14: =0 -> 0 | C14: =C12*'COSTO x UNIDAD'!B30 -> 18261800 | D14: =D12*AVERAGE('COSTO x UNIDAD'!B30,'COSTO x UNIDAD'!C30) -> 30999325 | E14: =E12*'COSTO x UNIDAD'!C30 -> 42915000 | F14: =F12*AVERAGE('COSTO x UNIDAD'!C30,'COSTO x UNIDAD'!D30) -> 54602600 | G14: =G12*'COSTO x UNIDAD'!D30 -> 69851300
A15: (=) Margen Bruto | B15: =B13-B14 -> 0 | C15: =C13-C14 -> 23753400 | D15: =D13-D14 -> 42527275 | E15: =E13-E14 -> 62123000 | F15: =F13-F14 -> 81946800 | G15: =G13-G14 -> 108713300
A16: (-) Costo financiero (intereses préstamo) | B16: =0 -> 0 | C16: ='AMORTIZACIÓN BANCARIA'!D13 -> 2076964 | D16: ='AMORTIZACIÓN BANCARIA'!D14 -> 757049 | E16: ='AMORTIZACIÓN BANCARIA'!D15 -> 569341 | F16: ='AMORTIZACIÓN BANCARIA'!$E$9-('AMORTIZACIÓN BANCARIA'!E15-'AMORTIZACIÓN BANCARIA'!$E$7) -> 361979 | G16: ='AMORTIZACIÓN BANCARIA'!$E$9-('AMORTIZACIÓN BANCARIA'!$E$7-'AMORTIZACIÓN BANCARIA'!$E$8) -> 132867
A17: (=) Utilidad Operacional | B17: =0 -> 0 | C17: =ROUND(C15-C10-(('EQUIPAMIENTO LAB'!D22-'EQUIPAMIENTO LAB'!D21)/6+'EQUIPAMIENTO LAB'!D21/7)-C16,0) -> 3918394 | D17: =ROUND(D15-D10-(('EQUIPAMIENTO LAB'!D22-'EQUIPAMIENTO LAB'!D21)/6+'EQUIPAMIENTO LAB'!D21/7)-D16,0) -> 11969036 | E17: =ROUND(E15-E10-(('EQUIPAMIENTO LAB'!D22-'EQUIPAMIENTO LAB'!D21)/6+'EQUIPAMIENTO LAB'!D21/7)-E16,0) -> 5302469 | F17: =ROUND(F15-F10-(('EQUIPAMIENTO LAB'!D22-'EQUIPAMIENTO LAB'!D21)/6+'EQUIPAMIENTO LAB'!D21/7)-F16,0) -> 14303631 | G17: =ROUND(G15-G10-(('EQUIPAMIENTO LAB'!D22-'EQUIPAMIENTO LAB'!D21)/6+'EQUIPAMIENTO LAB'!D21/7)-G16,0) -> 24249243
A18: (-) Impuesto renta (25%) | B18: =0 -> 0 | C18: =ROUND(MAX(0,C17*$B$6),0) -> 979599 | D18: =ROUND(MAX(0,D17*$B$6),0) -> 2992259 | E18: =ROUND(MAX(0,E17*$B$6),0) -> 1325617 | F18: =ROUND(MAX(0,F17*$B$6),0) -> 3575908 | G18: =ROUND(MAX(0,G17*$B$6),0) -> 6062311
A19: (=) Utilidad Neta | B19: =B17-B18 -> 0 | C19: =C17-C18 -> 2938795 | D19: =D17-D18 -> 8976777 | E19: =E17-E18 -> 3976852 | F19: =F17-F18 -> 10727723 | G19: =G17-G18 -> 18186932
A21: FLUJO DE CAJA | B21: AÑO 0 | C21: AÑO 1 | D21: AÑO 2 | E21: AÑO 3 | F21: AÑO 4 | G21: AÑO 5
A22: Inversión inicial | B22: =-'INVERSIÓN INICIAL'!B16 -> -23900000 | C22: =0 -> 0 | D22: =0 -> 0 | E22: =0 -> 0 | F22: =0 -> 0 | G22: =0 -> 0
A23: Utilidad neta | B23: =0 -> 0 | C23: =C19 -> 2938795 | D23: =D19 -> 8976777 | E23: =E19 -> 3976852 | F23: =F19 -> 10727723 | G23: =G19 -> 18186932
A24: (-) Amortización capital préstamo | B24: =0 -> 0 | C24: ='AMORTIZACIÓN BANCARIA'!C13 -> 6622676 | D24: ='AMORTIZACIÓN BANCARIA'!C14 -> 1792591 | E24: ='AMORTIZACIÓN BANCARIA'!C15 -> 1980299 | F24: ='AMORTIZACIÓN BANCARIA'!E15-'AMORTIZACIÓN BANCARIA'!$E$7 -> 2187661 | G24: ='AMORTIZACIÓN BANCARIA'!$E$7-'AMORTIZACIÓN BANCARIA'!$E$8 -> 2416773
A25: FLUJO NETO DEL PERÍODO | B25: =B22 -> -23900000 | C25: =ROUND(C23+(('EQUIPAMIENTO LAB'!D22-'EQUIPAMIENTO LAB'!D21)/6+'EQUIPAMIENTO LAB'!D21/7)-C24,0) -> -2872691 | D25: =ROUND(D23+(('EQUIPAMIENTO LAB'!D22-'EQUIPAMIENTO LAB'!D21)/6+'EQUIPAMIENTO LAB'!D21/7)-D24,0) -> 7995376 | E25: =ROUND(E23+(('EQUIPAMIENTO LAB'!D22-'EQUIPAMIENTO LAB'!D21)/6+'EQUIPAMIENTO LAB'!D21/7)-E24,0) -> 2807743 | F25: =ROUND(F23+(('EQUIPAMIENTO LAB'!D22-'EQUIPAMIENTO LAB'!D21)/6+'EQUIPAMIENTO LAB'!D21/7)-F24,0) -> 9351252 | G25: =ROUND(G23+(('EQUIPAMIENTO LAB'!D22-'EQUIPAMIENTO LAB'!D21)/6+'EQUIPAMIENTO LAB'!D21/7)-G24,0) -> 16581349
A26: FLUJO ACUMULADO | B26: =B25 -> -23900000 | C26: =B26+C25 -> -26772691 | D26: =C26+D25 -> -18777315 | E26: =D26+E25 -> -15969572 | F26: =E26+F25 -> -6618320 | G26: =F26+G25 -> 9963029
A28: ="CÁLCULO DEL VAN (r = "&TEXT(B5,"0%")&")" -> CÁLCULO DEL VAN (r = 20%)
A29: Factor descuento (1+r)^n | B29: =1 -> 1 | C29: =(1+$B$5)^1 -> 1.2 | D29: =(1+$B$5)^2 -> 1.44 | E29: =(1+$B$5)^3 -> 1.728 | F29: =(1+$B$5)^4 -> 2.0736 | G29: =(1+$B$5)^5 -> 2.48832
A30: Valor Presente de flujos | B30: =0 -> 0 | C30: =ROUND(C25/C29,0) -> -2393909 | D30: =ROUND(D25/D29,0) -> 5552344 | E30: =ROUND(E25/E29,0) -> 1624851 | F30: =ROUND(F25/F29,0) -> 4509670 | G30: =ROUND(G25/G29,0) -> 6663672
A31: Sumatoria VP flujos | C31: 0 | D31: 0 | E31: 0 | F31: 0 | G31: =SUM(C30:G30) -> 15956628
A32: Inversión inicial | B32: =B22 -> -23900000 | C32: 0 | D32: 0 | E32: 0 | F32: 0 | G32: 0
A33: VAN (Valor Actual Neto) | B33: =G31+B32 -> -7943372 | C33: 0 | D33: 0 | E33: 0 | F33: 0 | G33: 0
A34: Resultado | B34: =IF(B33>=0,"✅ VAN POSITIVO","❌ VAN NEGATIVO") -> ❌ VAN NEGATIVO
A36: PAY BACK | B36: AÑO 0 | C36: AÑO 1 | D36: AÑO 2 | E36: AÑO 3 | F36: AÑO 4 | G36: AÑO 5
A37: Flujo acumulado | B37: =B26 -> -23900000 | C37: =C26 -> -26772691 | D37: =D26 -> -18777315 | E37: =E26 -> -15969572 | F37: =F26 -> -6618320 | G37: =G26 -> 9963029
A38: ¿Inversión recuperada? | B38: =IF(B37>=0,"SÍ ✅","NO ❌") -> NO ❌ | C38: =IF(C37>=0,"SÍ ✅","NO ❌") -> NO ❌ | D38: =IF(D37>=0,"SÍ ✅","NO ❌") -> NO ❌ | E38: =IF(E37>=0,"SÍ ✅","NO ❌") -> NO ❌ | F38: =IF(F37>=0,"SÍ ✅","NO ❌") -> NO ❌ | G38: =IF(G37>=0,"SÍ ✅","NO ❌") -> SÍ ✅
A40: TOMA DE DECISIONES
A41: ="1. En base al VAN (r = "&TEXT(B5,"0%")&"):" -> 1. En base al VAN (r = 20%):
A42: ="VAN = CLP "&TEXT(B33,"#,##0") -> VAN = CLP -7943372,0
A43: =IF(B33>=0,"✅ Cumple la tasa exigida","❌ No cumple la tasa exigida") -> ❌ No cumple la tasa exigida
A44: ="TIR = "&TEXT(IRR(B25:G25),"0.0%") -> TIR = 09%
A46: 2. En base al PAY BACK:
...

Sheet COSTO x UNIDAD
A1: ESTRUCTURA DE COSTOS POR UNIDAD Y PRECIO DE VENTA
A2: TerraSense — Año 1
A4: COSTO VARIABLE / UNIDAD | B4: CLP | C4: Detalle
A5: Componentes electrónicos y sistema (BOM) | B5: ='BOM - COMPONENTES'!K31 -> 70656 | C5: Ver hoja BOM
A6: Flete nacional | B6: =6000 -> 6000 | C6: Bluexpress
A7: Merma y scrap | B7: =ROUND(B5*3%,0) -> 2120 | C7: 3% del BOM
A8: Provisión garantía legal | B8: =ROUND(B5*5%,0) -> 3533 | C8: 5% del BOM
A9: Mano de obra directa | B9: =9000 -> 9000 | C9: 1,5 h × $6.000
A10: COSTO TOTAL / UNIDAD | B10: =SUM(B5:B9) -> 91309
A12: PRECIO DE VENTA
A13: Costo variable / unidad | B13: =B10 -> 91309
A14: Margen de ganancia | B14: =PARÁMETROS!B14 -> 0.56535177
A15: Precio de Venta (PVP) | B15: =ROUND(B13/(1-B14)*1.19,0) -> 249990 | C15: CLP con IVA
A16: IVA incluido (19%) | B16: =-ROUND(B15*19/119,0) -> -39914 | C16: Débito fiscal
A17: Precio Neto Recibido | B17: =B15+B16 -> 210076 | C17: Sin IVA
A18: UTILIDAD NETA / UNIDAD | B18: =B17-B13 -> 118767 | C18: Margen contribución antes de gastos fijos
A20: BREAK-EVEN
A21: Inversión Inicial Total | B21: ='INVERSIÓN INICIAL'!B16 -> 23900000 | C21: CLP
A22: Utilidad neta / unidad | B22: =B18 -> 118767 | C22: Contribución
A23: Unidades necesarias para recuperar inversión | B23: =ROUNDUP(('PROYECCIÓN + VAN'!C15-'PROYECCIÓN + VAN'!C17)/B18,0) -> 168 | C23: Punto equilibrio contable Año 1
A25: COMPARATIVA POR LOTE | B25: Año 1 | C25: Año 3 | D25: Año 5
A26: Componentes | B26: =B5 -> 70656 | C26: =ROUND(B5*94%,0) -> 66417 | D26: =ROUND(B5*90%,0) -> 63590
A27: PCB / escala | B27: =0 -> 0 | C27: =0 -> 0 | D27: =0 -> 0
A28: Carcasa / escala | B28: =0 -> 0 | C28: =0 -> 0 | D28: =0 -> 0
A29: Otros costos variables | B29: =B30-B26 -> 20653 | C29: =C30-C26 -> 19413 | D29: =D30-D26 -> 18588
A30: COSTO TOTAL / UNIDAD | B30: =B10 -> 91309 | C30: =ROUND(B10*94%,0) -> 85830 | D30: =ROUND(B10*90%,0) -> 82178
