Workbook

Sheet PORTADA
B2: TERRASENSE — EVALUACIÓN ECONÓMICA DEL PROYECTO
B3: Inversiones, financiamiento, depreciación, amortización, estado de resultados, flujo de caja, VAN, TIR y Pay Back
B5: NOMBRE ESTUDIANTES: | C5: Álvaro Villena
B6: PROYECTO: | C6: TerraSense — Sistema IoT de diagnóstico agronómico prescriptivo
B7: CARRERA: | C7: Ingeniería en Electrónica y Sistemas Inteligentes, INACAP
B8: FUENTE DE LOS DATOS: | C8: README.md del proyecto, Sección XII (versión 3.0)
B9: MONEDA: | C9: Pesos chilenos (CLP), valores netos sin IVA
B10: HORIZONTE DE EVALUACIÓN: | C10: 5 años, tasa de rentabilidad exigida 20 % anual
B12: ÍNDICE DE LA PLANILLA
B13: Hoja | C13: Contenido | D13: Cuadro de la planilla
B14: PARÁMETROS | C14: Tabla maestra de supuestos: macro, precio, volumen, financiamiento y vidas útiles | D14: Base del modelo
B15: COSTOS UNITARIOS | C15: BOM unitario, costo variable entregado y curva de costo por escala | D15: Insumo del Cuadro N° 2
B16: INVERSIONES | C16: Inversión en capital de trabajo, activo nominal y activo fijo, con sus fuentes | D16: CUADRO N° 1
B17: FINANCIAMIENTO | C17: Fuentes de financiamiento y condiciones del crédito (FOGAPE y corto plazo) | D17: CUADRO N° 1
B18: AMORTIZACIÓN | C18: Amortización de ambos préstamos, sistema francés, y consolidado anual | D18: CUADRO N° 1
B19: DEPRECIACIÓN | C19: Depreciación anual del activo fijo, ítem por ítem y por grupo | D19: CUADRO N° 1
B20: ESTADO DE RESULTADOS | C20: Ingresos, costos y gastos operacionales del Año 1 (valor mes y valor año) | D20: CUADRO N° 2
B21: GASTOS FIJOS 5 AÑOS | C21: Escalamiento de los gastos fijos a 5 años y punto de equilibrio por año | D21: Apoyo al Cuadro N° 3
B22: PROYECCIÓN | C22: Estado de resultados proyectado, flujo de fondos, VAN, TIR y Pay Back | D22: CUADRO N° 3
B23: SENSIBILIDAD | C23: Sensibilidad, punto de quiebre y VAN frente a la tasa de descuento | D23: Complemento
B24: TOMA DE DECISIONES | C24: Toma de decisiones en base al VAN/TIR y en base al Pay Back | D24: Toma de decisiones
B25: RÚBRICA | C25: Rúbrica de evaluación e instrucciones de entrega | D25: Referencia
B27: RESULTADO DE LA EVALUACIÓN (todo calculado en la hoja PROYECCIÓN)
B28: Indicador | C28: Valor | D28: Criterio | E28: Veredicto
B29: Inversión inicial total | C29: =INVERSIONES!C45 | D29: — | E29: Financiada ≈34 % socios / ≈66 % banca
B30: VAN (tasa exigida 20 %) | C30: =PROYECCIÓN!C35 | D30: VAN > 0 | E30: =IF(PROYECCIÓN!C35>0,"✔ Cumple","✘ No cumple a 5 años")
B31: TIR | C31: =PROYECCIÓN!C37 | D31: TIR > 20 % | E31: =IF(PROYECCIÓN!C37>PROYECCIÓN!C30,"✔ Cumple","✘ No cumple, pero es positiva")
B32: Pay Back | C32: =PROYECCIÓN!C41 | D32: ≤ 5 años | E32: =IF(PROYECCIÓN!C41<=5,"✔ Cumple, sin holgura","✘ No cumple")
B33: Punto de equilibrio Año 1 (unidades) | C33: ='GASTOS FIJOS 5 AÑOS'!C29 | D33: < 200 u planificadas | E33: =IF('GASTOS FIJOS 5 AÑOS'!C29<'GASTOS FIJOS 5 AÑOS'!C23,"✔ Holgura del "&TEXT('GASTOS FIJOS 5 AÑOS'!C30,"0%"),"✘ No cumple")
B34: Utilidad neta de todos los años | C34: =IF(MIN(PROYECCIÓN!D17:H17)>0,"Positiva desde el Año 1","Hay años con pérdida") | D34: Sin años de pérdida | E34: =IF(MIN(PROYECCIÓN!D17:H17)>0,"✔ Cumple","✘ No cumple")
B36: Planilla íntegramente formulada. Los únicos valores digitados están en PARÁMETROS, COSTOS UNITARIOS, INVERSIONES y GASTOS FIJOS 5 AÑOS; el resto se encadena hasta el VAN. Cambiar un supuesto en PARÁMETROS recalcula toda la evaluación.
B37: Se declara con la misma honestidad que antes: a 5 años y 20 % el VAN ahora es POSITIVO ($2.588.182) y la TIR (≈22,7 %) supera la tasa exigida. El proyecto se acepta bajo el criterio estándar de la planilla, sujeto a confirmar en terreno la tasa de la línea de corto plazo (15 % anual estimado) y la dotación reducida de ensambladores. El detalle completo está en TOMA DE DECISIONES.

Sheet PARÁMETROS
B2: TABLA MAESTRA DE PARÁMETROS DEL MODELO
B3: README XII.1 · Modificar un valor de esta hoja propaga el cambio a toda la planilla
B4: 1. SUPUESTOS MACROECONÓMICOS Y TRIBUTARIOS
B5: Parámetro | C5: Valor adoptado | H5: Origen
B6: Tipo de cambio (CLP/USD) | C6: 915 | H6: Dólar observado, Banco Central de Chile [35]
B7: IVA | C7: 0.19 | H7: SII [34]
B8: Impuesto de primera categoría (Régimen Pro Pyme General) | C8: 0.25 | H8: SII [57]
B9: Arancel de importación sobre valor FOB | C9: 0.06 | H9: Aduanas [32]
B10: Tasa de rentabilidad exigida / de descuento (r) | C10: 0.2 | H10: Tasa exigida por la planilla de evaluación
B11: Margen mínimo exigido sobre costo total | C11: 0.3 | H11: Restricción de negocio del proyecto
B12: Horizonte de evaluación (años) | C12: 5 | H12: Planilla de evaluación económica
B14: 2. PRODUCTO, PRECIO Y COSTOS UNITARIOS DE REFERENCIA
B15: Parámetro | C15: Valor adoptado | H15: Origen
B16: Precio de venta con IVA (techo declarado del negocio) | C16: 249990 | H16: Decisión de negocio, verificada contra la competencia (XI.3)
B17: Precio de venta NETO (sin IVA) | C17: =ROUND(C16/(1+C7),0) | H17: precio con IVA ÷ (1 + IVA)
B18: Merma y scrap | C18: 0.03 | H18: Estimación propia
B19: Provisión de garantía legal, 6 meses | C19: 0.05 | H19: Ley 21.398 [24]
B20: Mano de obra directa: horas de ensamblaje y QA por unidad | C20: 1.5 | H20: XI.6 — subió desde 1,2 h por la sonda de mayor costo y el sellado adicional
B21: Valor hora de mano de obra directa | C21: 6000 | H21: Estimación propia
B22: Flete nacional al cliente, por unidad (Bluexpress) | C22: 6000 | H22: Tarifa referencial ~$4.500 + IVA por kg
B24: 3. VOLUMEN PROYECTADO Y CURVA DE ESCALA
B25: Parámetro | C25: Año 1 | D25: Año 2 | E25: Año 3 | F25: Año 4 | G25: Año 5 | H25: Origen
B26: Unidades planificadas | C26: 200 | D26: 350 | E26: 500 | F26: 650 | G26: 850 | H26: XI.1 — 200 u equivalen al 0,17 % del mercado servible
B27: Factor de costo variable por escala | C27: 1 | D27: 0.97 | E27: 0.94 | F27: 0.92 | G27: 0.9 | H27: XII.2.3 — NRE prorrateado, quiebres de precio y flete consolidado
B29: 4. FINANCIAMIENTO
B30: Parámetro | C30: Valor adoptado | H30: Naturaleza
B31: Inversión inicial total del proyecto | C31: =INVERSIONES!C45 | H31: Calculada en la hoja INVERSIONES
B32: Pie de los socios (2 × $4.450.000, aporte propio) | C32: 8900000 | H32: Compromiso de capital que el banco exige ver antes de aprobar
B33: Crédito bancario de largo plazo | C33: =C31-C32-C36-C40 | H33: Crédito PYME con garantía FOGAPE; monto = inversión total − pie − línea corta (se ajusta automáticamente si cambia algún supuesto)
B34: Tasa de interés anual, largo plazo | C34: 0.1 | H34: Crédito PYME con garantía FOGAPE
B35: Plazo del crédito de largo plazo (años) | C35: 5 | H35: 5 años
B36: Línea de crédito de corto plazo | C36: 5000000 | H36: Cubre el desfase de caja del primer lote
B37: Tasa de interés anual, corto plazo | C37: 0.15 | H37: Línea de capital de trabajo con garantía FOGAPE; monto acotado (~$5 MM) → tasa de mercado para PYME garantizada, no de línea sin garantía (validar con cotización real de 2-3 bancos antes de firmar)
B38: Plazo de la línea de corto plazo (años) | C38: 1 | H38: Se paga íntegra dentro del Año 1
B39: Sistema de amortización | C39: Francés (cuota total constante) | H39: XII.3.4
B40: Financiamiento del Estado (subsidio no reembolsable) | C40: 0 | H40: Por decisión explícita: el proyecto no depende de un fondo CORFO
B42: 5. ACTIVO FIJO, DEPRECIACIÓN Y REMUNERACIONES
B43: Parámetro | C43: Valor adoptado | H43: Origen
B44: Vida útil — equipamiento técnico e informático (años) | C44: 6 | H44: Tabla de vida útil de bienes físicos del SII [59]
B45: Vida útil — mobiliario de taller y almacenamiento (años) | C45: 7 | H45: Tabla de vida útil de bienes físicos del SII [59]
...

Sheet COSTOS UNITARIOS
B2: ESTRUCTURA DE COSTOS UNITARIOS
B3: README XII.2 · 100 % SMD, componentes cotizados en LCSC y PCBA en JLCPCB
B4: 1. LISTA DE MATERIALES (BOM) UNITARIA
B5: Componente | C5: Fuente / detalle | D5: Costo unitario $
B6: ESP32-WROOM-32E-N4, BME280, SP3485, TP4056, MT3608, Si2301 + pasivos | C6: LCSC, precio unitario a pieza suelta | D6: 6711
B7: PCB de 2 capas + ensamblaje SMT + NRE prorrateado | C7: JLCPCB turnkey | D7: 2229
B8: Flete internacional + arancel del 6 % | C8: Courier consolidado sobre el lote electrónico | D8: 1183
B9: 2× celda 18650 de 3.000 mAh + portacelda + fusible | C9: Cotización de mercado | D9: 4510
B10: USB-C sellado, rocker, pulsador PAIR, prensaestopas M12, O-ring, insertos M3 | C10: Cotización de mercado | D10: 3250
B11: Filamento PETG (118 g) + energía de impresión | C11: Inversión y consumo propios (estimación) | D11: 2273
B12: Empaque: caja, manual, espuma y desecante | C12: Estimación propia | D12: 2500
B13: Sonda de suelo 7-en-1 RS-485, acero inoxidable 316L | C13: Cotización real de mercado | D13: 48000
B14: BOM TOTAL | D14: =SUM(D6:D13)
B15: El BOM subió de $43.773 a $70.656 (+61 %) casi enteramente por la sonda ($16.500 → $48.000, la cifra real de mercado). La electrónica en sí bajó al pasar todo a componentes SMD cotizados directo en LCSC en vez de módulos premontados.
B17: 2. DEL BOM AL COSTO VARIABLE UNITARIO ENTREGADO (AÑO 1)
B18: Concepto | C18: Cálculo | D18: Monto $
B19: BOM | C19: Total del cuadro 1 | D19: =D14
B20: (+) Flete nacional al cliente (Bluexpress) | C20: Parámetro | D20: =PARÁMETROS!C22
B21: (+) Merma y scrap (3 %) | C21: BOM × 3 % | D21: =ROUND(D19*PARÁMETROS!C18,0)
B22: (+) Provisión de garantía legal, 6 meses (5 %) | C22: BOM × 5 % | D22: =ROUND(D19*PARÁMETROS!C19,0)
B23: (+) Mano de obra directa: ensamblaje, QA y calibración | C23: 1,5 h × $6.000 por hora | D23: =PARÁMETROS!C20*PARÁMETROS!C21
B24: (=) COSTO VARIABLE UNITARIO — AÑO 1 | D24: =SUM(D19:D23)
B25: El IVA de importación no es un costo: se compensa como crédito fiscal contra el IVA débito de las ventas. Todo el modelo trabaja en valores netos, sin IVA, tanto en ingresos como en costos.
B27: 3. CURVA DE COSTO VARIABLE UNITARIO POR ESCALA
B28: Año | C28: Unidades planificadas | D28: Factor | E28: Costo variable unitario $ | F28: Origen de la reducción
B29: Año 1 | C29: =PARÁMETROS!C26 | D29: =PARÁMETROS!C27 | E29: =ROUND($D$24*D29,0) | F29: Sin reducción — es el costo base del Año 1
B30: Año 2 | C30: =PARÁMETROS!D26 | D30: =PARÁMETROS!D27 | E30: =ROUND($D$24*D30,0) | F30: NRE de PCB amortizado en un lote mayor
B31: Año 3 | C31: =PARÁMETROS!E26 | D31: =PARÁMETROS!E27 | E31: =ROUND($D$24*D31,0) | F31: Quiebres de precio por volumen en componentes LCSC
B32: Año 4 | C32: =PARÁMETROS!F26 | D32: =PARÁMETROS!F27 | E32: =ROUND($D$24*D32,0) | F32: Consolidación de flete en lotes mayores
B33: Año 5 | C33: =PARÁMETROS!G26 | D33: =PARÁMETROS!G27 | E33: =ROUND($D$24*D33,0) | F33: Negociación directa con el proveedor de la sonda
B35: 4. DESGLOSE DEL COSTO VARIABLE UNITARIO PARA EL CUADRO N° 2
B36: Componente del costo variable | C36: Clasificación en el Cuadro N° 2 | D36: Monto unitario $
B37: Materiales directos (BOM) | C37: Costo operacional — materiales directos | D37: =D14
B38: Flete nacional, merma y provisión de garantía legal | C38: Costo operacional — otros costos variables | D38: =D20+D21+D22
B39: Mano de obra directa (ensamblaje, QA y calibración) | C39: Costo operacional — mano de obra directa | D39: =D23
B40: TOTAL COSTO VARIABLE UNITARIO | D40: =SUM(D37:D39)

Sheet INVERSIONES
B2: CUADRO N° 1 — INVERSIONES DEL PROYECTO
B3: Álvaro Villena · Inversión inicial clasificada y sus fuentes de financiamiento (README XII.3)
D5: FUENTES DE FINANCIAMIENTO
D6: FINANCIAMIENTO DEL ESTADO | E6: CAPITAL | F6: FINANCIAMIENTO EXTERNO — INSTITUCIONES FINANCIERAS | H6: TOTAL
B7: INVERSIÓN INICIAL EN: | C7: MONTO $ | D7: (no aplica) | E7: PROPIO — PIE DE LOS 2 SOCIOS | F7: CORTO PLAZO | G7: LARGO PLAZO | H7: FINANCIAMIENTO $
B9: (A) INVERSIÓN INICIAL EN CAPITAL DE TRABAJO Y ACTIVO NOMINAL
B10: Dinero para cubrir la puesta en marcha: constitución de la empresa, ensayos, patentes, marca y primer lote
B11: Trámites y gastos de constituir la empresa, desglosados uno a uno — se deja en $0 lo que es gratuito o no aplica, no se omite:
B12: Constitución de la SpA vía "Empresa en un Día" (trámite + notaría digital, 2 socios) | C12: 0
B13: Firma electrónica avanzada (FEA) para ambos socios | C13: 30000
B14: Inicio de actividades SII, timbraje electrónico y apertura de cuenta corriente empresa | C14: 0
B15: Registro de marca comercial ante INAPI (1 clase) | C15: 220000
B16: Patente municipal — permiso de actividad en casa, primer año | C16: 35000
B17: Resolución sanitaria y certificación SEC — no aplica (no es alimento/fármaco ni equipo conectado a la red) | C17: 0
B18: Honorarios contables de puesta en marcha (aparte de la asesoría mensual, ver GASTOS FIJOS) | C18: 100000
B19: Ensayos de contraste agronómico en laboratorio (30 muestras) | C19: 900000
B20: Ensayos externos de estanqueidad IP67 y compatibilidad electromagnética | C20: 1500000
B21: Sitio web e-commerce (Shopify), identidad de marca y material comercial | C21: 450000
B22: Patrones de calibración (buffers de pH y EC 1.413 µS/cm) | C22: 120000
B23: Herramienta menor, tornillería, insertos y consumibles | C23: 150000
B24: Lote piloto de validación (10 unidades preserie × costo variable unitario) | C24: =10*'COSTOS UNITARIOS'!$D$24
B25: Subtotal activo nominal | C25: =SUM(C12:C24)
B26: Capital de trabajo (≈3 meses de gasto fijo pleno + primer lote de 100 unidades pagado por adelantado) | C26: 14806910
B27: Contingencia / imprevistos (10 % sobre el subtotal de la inversión, A + B) | C27: =ROUND(0.1*(C25+C26+C43),0)
B28: TOTAL CAPITAL DE TRABAJO, ACTIVO NOMINAL Y CONTINGENCIA (A) | C28: =C25+C26+C27 | D28: =PARÁMETROS!C40 | E28: =PARÁMETROS!C32 | F28: =PARÁMETROS!C36 | G28: =PARÁMETROS!C33-G43 | H28: =SUM(D28:G28)
B30: (B) INVERSIÓN INICIAL EN ACTIVO FIJO
B31: No hay terrenos, construcciones ni vehículos: la producción cabe en la casa de los dos socios y la logística se resuelve por Bluexpress
B32: Impresora 3D FDM principal, cámara cerrada | C32: 900000 | D32: Equipamiento
B33: Impresora 3D FDM secundaria (redundancia operacional) | C33: 450000 | D33: Equipamiento
B34: Secador de filamento y almacenamiento estanco | C34: 80000 | D34: Equipamiento
B35: Estación de soldadura, aire caliente y microscopio USB | C35: 240000 | D35: Equipamiento
B36: Fuente de poder programable y multímetro de banco | C36: 250000 | D36: Equipamiento
B37: Osciloscopio de 100 MHz, 2 canales | C37: 400000 | D37: Equipamiento
B38: Analizador lógico, programador y sonda de corriente de µA | C38: 160000 | D38: Equipamiento
B39: Banco de ensayo IP67 (columna de 1 m + cámara de polvo) | C39: 180000 | D39: Equipamiento
B40: Instrumento patrón de laboratorio (pH/EC) | C40: 350000 | D40: Equipamiento
B41: 2× notebook y puesto de desarrollo (uno por socio) | C41: 1600000 | D41: Equipamiento
B42: Mobiliario de taller y almacenamiento (casa de ambos socios) | C42: 300000 | D42: Mobiliario
B43: TOTAL ACTIVO FIJO (B) | C43: =SUM(C32:C42) | G43: =C43 | H43: =SUM(D43:G43)
B45: TOTAL INVERSIÓN INICIAL (A) + (B) | C45: =C28+C43 | D45: =D28+D43 | E45: =E28+E43 | F45: =F28+F43 | G45: =G28+G43 | H45: =H28+H43
...

Sheet FINANCIAMIENTO
B2: FUENTES DE FINANCIAMIENTO Y CONDICIONES DEL CRÉDITO
B3: README XII.3.3 · Pie de los dos socios + crédito bancario, sin subsidio estatal
B4: 1. FUENTES DE FINANCIAMIENTO
B5: Fuente | C5: Monto $ | D5: % del total | F5: Naturaleza
B6: Pie de los socios (2 × $4.450.000, aporte propio) | C6: =PARÁMETROS!C32 | D6: =C6/$C$10 | F6: Pie de capital propio de los 2 socios (.450.000 c/u) depositado como patrimonio líquido en la cuenta corriente de la empresa
B7: Crédito bancario de largo plazo — 5 años, 10 % anual | C7: =PARÁMETROS!C33 | D7: =C7/$C$10 | F7: Crédito comercial bancario a 5 años (60 meses) con cuota constante sistema francés (.336.642/año), con garantía FOGAPE y aval de los socios
B8: Línea de corto plazo — 1 año, 15 % anual | C8: =PARÁMETROS!C36 | D8: =C8/$C$10 | F8: Cubre el desfase de caja mientras se paga el primer lote de sondas y electrónica; el monto es acotado (~$5 MM) y cuenta con garantía FOGAPE, por lo que el banco la aprueba a una tasa cercana a la de PYME garantizada y no a la de una línea de crédito de consumo sin garantía
B9: Financiamiento del Estado (subsidio no reembolsable) | C9: =PARÁMETROS!C40 | D9: =C9/$C$10 | F9: Cero por decisión explícita: postular a CORFO sigue abierto, pero el proyecto debe poder sostenerse sin él
B10: TOTAL FINANCIAMIENTO | C10: =SUM(C6:C9) | D10: =SUM(D6:D9)
B11: Inversión inicial a financiar (hoja INVERSIONES) | C11: =INVERSIONES!C45
B12: =IF(C10=C11,"✔ VERIFICACIÓN: el financiamiento cubre exactamente la inversión inicial","✘ DESCUADRE entre financiamiento e inversión")
B13: Ningún banco chileno presta el 100 % de la inversión a una empresa recién constituida, aunque tenga garantía FOGAPE: la garantía cubre el riesgo del banco, no reemplaza el compromiso de capital propio. El ≈34 % de aporte de los socios es lo que hace aprobable el crédito.
B15: 2. CONDICIONES DE CADA CRÉDITO
B16: Concepto | C16: Largo plazo | D16: Corto plazo | F16: Comentario
B17: Tipo de fuente | C17: Crédito bancario PYME con garantía FOGAPE | D17: Línea de capital de trabajo | F17: Ambas de instituciones financieras
B18: Sistema de amortización | C18: Francés (cuota total constante) | D18: Pago único al vencimiento | F18: XII.3.4
B19: Monto del préstamo (capital / VA) | C19: =PARÁMETROS!C33 | D19: =PARÁMETROS!C36 | F19: Suman ≈66 % de la inversión
B20: Tasa de interés anual | C20: =PARÁMETROS!C34 | D20: =PARÁMETROS!C37 | F20: La línea corta es deuda cara: se paga primero
B21: Plazo (años) | C21: =PARÁMETROS!C35 | D21: =PARÁMETROS!C38 | F21: El corto plazo se extingue dentro del Año 1
B23: 3. RESULTADO DEL CRÉDITO
B24: Concepto | C24: Largo plazo | D24: Corto plazo | F24: Fórmula
B25: Cuota anual constante (sistema francés) | C25: =-PMT(C20,C21,C19) | D25: =-PMT(D20,D21,D19) | F25: PMT(tasa; plazo; capital)
B26: Total de intereses pagados | C26: =C25*C21-C19 | D26: =D25*D21-D19 | F26: Cuota × plazo − capital
B27: Total pagado al banco | C27: =C25*C21 | D27: =D25*D21 | F27: Capital + intereses
B28: COSTO FINANCIERO TOTAL DEL PROYECTO (LP + CP) | C28: =C26+D26
B29: Sin subsidio estatal, por decisión explícita: a diferencia de versiones anteriores del estudio, este modelo no depende de que se adjudique un fondo CORFO no reembolsable. Se financia enteramente con el aporte de los dos socios y crédito bancario.

Sheet AMORTIZACIÓN
B2: CÁLCULO DE LA AMORTIZACIÓN DE LOS PRÉSTAMOS Y LOS INTERESES
B3: README XII.3.4 · Sistema francés: la cuota total es constante y la composición capital/interés cambia cada año
B4: 1. FINANCIAMIENTO A LARGO PLAZO — CRÉDITO BANCARIO CON GARANTÍA FOGAPE
B5: Monto del préstamo (capital) | C5: =PARÁMETROS!C33
B6: Tasa de interés anual | C6: =PARÁMETROS!C34
B7: Plazo (años) | C7: =PARÁMETROS!C35
B8: Cuota anual constante | C8: =-PMT(C6,C7,C5)
B10: Período (año) | C10: Saldo insoluto $ | D10: Cuota total $ | E10: Amortización interés $ | F10: Amortización cuota capital $ | G10: Saldo final $
B11: 1 | C11: =$C$5 | D11: =$C$8 | E11: =C11*$C$6 | F11: =D11-E11 | G11: =C11-F11
B12: 2 | C12: =G11 | D12: =$C$8 | E12: =C12*$C$6 | F12: =D12-E12 | G12: =C12-F12
B13: 3 | C13: =G12 | D13: =$C$8 | E13: =C13*$C$6 | F13: =D13-E13 | G13: =C13-F13
B14: 4 | C14: =G13 | D14: =$C$8 | E14: =C14*$C$6 | F14: =D14-E14 | G14: =C14-F14
B15: 5 | C15: =G14 | D15: =$C$8 | E15: =C15*$C$6 | F15: =D15-E15 | G15: =C15-F15
B16: TOTALES | D16: =SUM(D11:D15) | E16: =SUM(E11:E15) | F16: =SUM(F11:F15)
B18: 2. FINANCIAMIENTO A CORTO PLAZO — LÍNEA DE CAPITAL DE TRABAJO
B19: Monto del préstamo (capital) | C19: =PARÁMETROS!C36
B20: Tasa de interés anual | C20: =PARÁMETROS!C37
B21: Plazo (años) | C21: =PARÁMETROS!C38
B22: Cuota anual constante | C22: =-PMT(C20,C21,C19)
B24: Período (año) | C24: Saldo insoluto $ | D24: Cuota total $ | E24: Amortización interés $ | F24: Amortización cuota capital $ | G24: Saldo final $
B25: 1 | C25: =$C$19 | D25: =$C$22 | E25: =C25*$C$20 | F25: =D25-E25 | G25: =C25-F25
B26: TOTALES | D26: =D25 | E26: =E25 | F26: =F25
B28: 3. COSTO FINANCIERO Y AMORTIZACIÓN DE CAPITAL CONSOLIDADOS (LO QUE USA EL CUADRO N° 3)
B29: Concepto | C29: Año 1 | D29: Año 2 | E29: Año 3 | F29: Año 4 | G29: Año 5
B30: Interés — costo financiero del ejercicio | C30: =E11+E25 | D30: =E12 | E30: =E13 | F30: =E14 | G30: =E15
B31: Amortización de la cuota de capital | C31: =F11+F25 | D31: =F12 | E31: =F13 | F31: =F14 | G31: =F15
B32: Cuota total pagada al banco (salida de caja) | C32: =C30+C31 | D32: =D30+D31 | E32: =E30+E31 | F32: =F30+F31 | G32: =G30+G31
B33: Saldo insoluto al cierre del ejercicio | C33: =G11+G25 | D33: =G12 | E33: =G13 | F33: =G14 | G33: =G15
B35: El Año 1 acumula el interés de ambos préstamos y la devolución íntegra de la línea de corto plazo: es el año de mayor carga financiera de todo el quinquenio, y el único con flujo de fondos negativo.

Sheet DEPRECIACIÓN
B2: CÁLCULO DE LA CUOTA DE DEPRECIACIÓN ANUAL
B3: README XII.3.5 · Depreciación lineal, valor residual cero, vidas útiles según la tabla del SII [59]
B4: 1. DETALLE DEL ACTIVO FIJO Y SU DEPRECIACIÓN
B5: Componente del activo fijo | C5: Grupo | D5: Valor de adquisición $ | E5: Vida útil (años) | F5: Depreciación anual $ | G5: Depreciación acumulada a 5 años $ | H5: Valor libro al Año 5 $
B6: =INVERSIONES!B32 | C6: =INVERSIONES!D32 | D6: =INVERSIONES!C32 | E6: =IF(C6="Mobiliario",PARÁMETROS!$C$45,PARÁMETROS!$C$44) | F6: =D6/E6 | G6: =F6*5 | H6: =D6-G6
B7: =INVERSIONES!B33 | C7: =INVERSIONES!D33 | D7: =INVERSIONES!C33 | E7: =IF(C7="Mobiliario",PARÁMETROS!$C$45,PARÁMETROS!$C$44) | F7: =D7/E7 | G7: =F7*5 | H7: =D7-G7
B8: =INVERSIONES!B34 | C8: =INVERSIONES!D34 | D8: =INVERSIONES!C34 | E8: =IF(C8="Mobiliario",PARÁMETROS!$C$45,PARÁMETROS!$C$44) | F8: =D8/E8 | G8: =F8*5 | H8: =D8-G8
B9: =INVERSIONES!B35 | C9: =INVERSIONES!D35 | D9: =INVERSIONES!C35 | E9: =IF(C9="Mobiliario",PARÁMETROS!$C$45,PARÁMETROS!$C$44) | F9: =D9/E9 | G9: =F9*5 | H9: =D9-G9
B10: =INVERSIONES!B36 | C10: =INVERSIONES!D36 | D10: =INVERSIONES!C36 | E10: =IF(C10="Mobiliario",PARÁMETROS!$C$45,PARÁMETROS!$C$44) | F10: =D10/E10 | G10: =F10*5 | H10: =D10-G10
B11: =INVERSIONES!B37 | C11: =INVERSIONES!D37 | D11: =INVERSIONES!C37 | E11: =IF(C11="Mobiliario",PARÁMETROS!$C$45,PARÁMETROS!$C$44) | F11: =D11/E11 | G11: =F11*5 | H11: =D11-G11
B12: =INVERSIONES!B38 | C12: =INVERSIONES!D38 | D12: =INVERSIONES!C38 | E12: =IF(C12="Mobiliario",PARÁMETROS!$C$45,PARÁMETROS!$C$44) | F12: =D12/E12 | G12: =F12*5 | H12: =D12-G12
B13: =INVERSIONES!B39 | C13: =INVERSIONES!D39 | D13: =INVERSIONES!C39 | E13: =IF(C13="Mobiliario",PARÁMETROS!$C$45,PARÁMETROS!$C$44) | F13: =D13/E13 | G13: =F13*5 | H13: =D13-G13
B14: =INVERSIONES!B40 | C14: =INVERSIONES!D40 | D14: =INVERSIONES!C40 | E14: =IF(C14="Mobiliario",PARÁMETROS!$C$45,PARÁMETROS!$C$44) | F14: =D14/E14 | G14: =F14*5 | H14: =D14-G14
B15: =INVERSIONES!B41 | C15: =INVERSIONES!D41 | D15: =INVERSIONES!C41 | E15: =IF(C15="Mobiliario",PARÁMETROS!$C$45,PARÁMETROS!$C$44) | F15: =D15/E15 | G15: =F15*5 | H15: =D15-G15
B16: =INVERSIONES!B42 | C16: =INVERSIONES!D42 | D16: =INVERSIONES!C42 | E16: =IF(C16="Mobiliario",PARÁMETROS!$C$45,PARÁMETROS!$C$44) | F16: =D16/E16 | G16: =F16*5 | H16: =D16-G16
B17: TOTAL ACTIVO FIJO | D17: =SUM(D6:D16) | F17: =SUM(F6:F16) | G17: =SUM(G6:G16) | H17: =SUM(H6:H16)
B19: 2. RESUMEN POR GRUPO DE ACTIVO (cifra que usa el Cuadro N° 3)
B20: Grupo de activo | C20: Valor de adquisición $ | D20: Vida útil (años) | E20: Depreciación anual $ | F20: Depreciación acumulada a 5 años $ | G20: Valor libro al Año 5 $
B21: Equipamiento técnico e informático (impresoras 3D, instrumentos, 2 notebooks) | C21: =SUMIF($C$6:$C$16,"Equipamiento",$D$6:$D$16) | D21: =PARÁMETROS!C44 | E21: =ROUND(C21/D21,0) | F21: =E21*5 | G21: =C21-F21
B22: Mobiliario de taller y almacenamiento | C22: =SUMIF($C$6:$C$16,"Mobiliario",$D$6:$D$16) | D22: =PARÁMETROS!C45 | E22: =ROUND(C22/D22,0) | F22: =E22*5 | G22: =C22-F22
B23: TOTAL — CUOTA DE DEPRECIACIÓN ANUAL DEL PROYECTO | C23: =SUM(C21:C22) | E23: =SUM(E21:E22) | F23: =SUM(F21:F22) | G23: =SUM(G21:G22)
B25: Valor residual cero. Vidas útiles conforme a la tabla de vida útil de bienes físicos del SII [59]: 6 años para equipamiento técnico e informático y 7 años para mobiliario. La depreciación no es salida de caja y por eso se devuelve al flujo de fondos.

Sheet ESTADO DE RESULTADOS
B2: CUADRO N° 2 — INGRESOS, COSTOS Y GASTOS OPERACIONALES (AÑO 1)
B3: Álvaro Villena · README XII.4 · El precio se fija en el techo declarado del negocio: $249.990 con IVA
D5: VALOR MES $ | E5: VALOR AÑO 1 $ | G5: ESTUDIO DE ORIGEN
C7: VENTAS | G7: ESTUDIO DE MERCADO
C8: Unidades vendidas | D8: =E8/12 | E8: =PARÁMETROS!C26
C9: Precio de venta neto por unidad, sin IVA ($249.990 ÷ 1,19) | E9: =PARÁMETROS!$C$17
C10: VT = unidades × precio neto | D10: =E10/12 | E10: =E8*E9
B11: (+) | C11: TOTAL VENTAS | D11: =D10 | E11: =E10
C13: COSTOS OPERACIONALES (COSTOS VARIABLES) | G13: ESTUDIO TÉCNICO
C14: Materiales directos (BOM): 200 unidades × $70.656 | D14: =E14/12 | E14: =$E$8*'COSTOS UNITARIOS'!D37
C15: Flete nacional, merma y provisión de garantía legal: 200 × $11.653 | D15: =E15/12 | E15: =$E$8*'COSTOS UNITARIOS'!D38
C16: Mano de obra directa — ensamblaje, QA y calibración: 200 × 1,5 h × $6.000 | D16: =E16/12 | E16: =$E$8*'COSTOS UNITARIOS'!D39
B17: (−) | C17: TOTAL COSTOS OPERACIONALES | D17: =SUM(D14:D16) | E17: =SUM(E14:E16)
C19: GASTOS DE ADMINISTRACIÓN (GASTOS FIJOS) | G19: ESTUDIO ADMINISTRATIVO
C20: Mano de obra indirecta — sueldo empresarial de los 2 socios (IMM, $553.553 c/u) | D20: =E20/12 | E20: =PARÁMETROS!C47*PARÁMETROS!C48*12
C21: Ensamblador — sin contratar el Año 1: lo cubren los dos socios (0,17 FTE) | D21: =E21/12 | E21: 0
C22: Servicios digitales y tiendas de aplicaciones | D22: =E22/12 | E22: =E48
C23: Gastos generales — energía e internet incremental (casa de ambos socios) | D23: =E23/12 | E23: 360000
C24: Contabilidad, patente municipal y asesoría legal | D24: =E24/12 | E24: 840000
C25: Materiales indirectos y seguros | D25: =E25/12 | E25: 420000
B26: (−) | C26: TOTAL GASTOS DE ADMINISTRACIÓN | D26: =SUM(D20:D25) | E26: =SUM(E20:E25)
C28: GASTOS DE COMERCIALIZACIÓN (GASTOS FIJOS) | G28: ESTUDIO DE MERCADO
C29: Publicidad y promoción — pauta digital directa en Google Ads y Meta Ads, sin agencia el Año 1 | D29: =E29/12 | E29: 1200000
B30: (−) | C30: TOTAL GASTOS DE COMERCIALIZACIÓN | D30: =D29 | E30: =E29
C32: TOTAL COSTOS Y GASTOS FIJOS (administración + comercialización) | D32: =D26+D30 | E32: =E26+E30
C33: TOTAL COSTOS Y GASTOS (CT) | D33: =D17+D32 | E33: =E17+E32
B35: (=) | C35: UTILIDAD (PÉRDIDA) OPERACIONAL — antes de depreciación e intereses | D35: =D11-D33 | E35: =E11-E33
C36: Margen implícito sobre el costo total (VT ÷ CT − 1) | E36: =E11/E33-1
B37: La planilla estándar deriva las ventas como VT = CT × (1 + % rentabilidad). Aquí el sentido de la fórmula se invierte por una razón de negocio: el precio ya está en su techo declarado ($249.990 con IVA), así que lo que se resuelve es cuántas unidades hacen falta para cubrir el costo total — y el margen implícito resultante es la consecuencia, no el punto de partida.
B39: DETALLE DE SERVICIOS DIGITALES Y TIENDAS DE APLICACIONES (AÑO 1)
C40: Servicio | D40: Referencia | E40: Costo anual $
C41: Supabase Pro (US$25 al mes) | D41: [38] | E41: 274500
C42: Apple Developer Program (US$99 al año) | D42: [36] | E42: 90585
C43: Google Play Console (US$25, pago único de por vida) | D43: [37] | E43: 22875
C44: Expo EAS Starter (US$19 al mes) | D44: [39] | E44: 208620
C45: Dominio, correo corporativo y alojamiento de la consola web | D45: Estimación | E45: 95000
C46: Google Maps Platform, sobre el tramo gratuito | D46: [40] | E46: 150000
C47: Open-Meteo (uso no comercial, gratuito por ahora) | D47: [41] | E47: 0
C48: TOTAL SERVICIOS DIGITALES | E48: =SUM(E41:E47)
B50: PUNTO DE EQUILIBRIO CONTABLE DEL AÑO 1
...

Sheet GASTOS FIJOS 5 AÑOS
B2: ESTRUCTURA DE GASTOS FIJOS POR AÑO Y JUSTIFICACIÓN DEL ESCALAMIENTO
B3: README XII.4.3 · El crecimiento no se modela con un índice genérico: se modela con la dotación y los arriendos reales de cada año
B4: GASTOS DE ADMINISTRACIÓN
B5: Concepto | C5: Año 1 | D5: Año 2 | E5: Año 3 | F5: Año 4 | G5: Año 5 | H5: Justificación del escalamiento
B6: Sueldo empresarial de los 2 socios | C6: ='ESTADO DE RESULTADOS'!E20 | D6: 14400000 | E6: 21600000 | F6: 24000000 | G6: 28800000 | H6: Sueldo empresarial (Art. 31 N° 6 LIR). Año 1: .553 c/u (IMM legal); Año 2: .000 c/u; Año 3: .000 c/u; Año 4: .000.000 c/u; Año 5: .200.000 c/u. Garantiza ingreso formal a Álvaro y Alan desde el mes 1 (.042.636 acumulados por socio a 5 años).
B7: → equivale a, por socio y por mes | C7: =C6/12/PARÁMETROS!$C$48 | D7: =D6/12/PARÁMETROS!$C$48 | E7: =E6/12/PARÁMETROS!$C$48 | F7: =F6/12/PARÁMETROS!$C$48 | G7: =G6/12/PARÁMETROS!$C$48
B8: Ensamblador(es) contratados | C8: 0 | D8: 3490000 | E8: 6980000 | F8: 6980000 | G8: 10460000 | H8: 0,5 FTE el Año 2, 1 FTE los Años 3 y 4, 1,5 FTE el Año 5 — dimensionado por horas reales (ensamblaje + QA + testing + embalaje, 2,25 h/unidad) sobre 1.800 h productivas por FTE al año, a sueldo IMM cargado (+5 % costo patronal), no por una dotación arbitraria creciente
B9: Arriendo de taller / oficina | C9: 0 | D9: 0 | E9: 4200000 | F9: 4200000 | G9: 5040000 | H9: Los Años 1 y 2 la producción cabe en la casa de los socios
B10: Servicios digitales y tiendas de aplicaciones | C10: ='ESTADO DE RESULTADOS'!E22 | D10: 850000 | E10: 900000 | F10: 950000 | G10: 1000000 | H10: Shopify, Supabase Pro, Apple Developer, Google Play, Expo, dominio y mapas
B11: Energía, agua e internet | C11: 360000 | D11: 420000 | E11: 1140000 | F11: 1140000 | G11: 1320000 | H11: Salta el Año 3 al incorporarse el taller arrendado
B12: Contabilidad, patente municipal y asesoría legal | C12: 840000 | D12: 960000 | E12: 1680000 | F12: 1680000 | G12: 1980000 | H12: Outsourcing contable Pyme (Contabilizate, TuContador, ChileContador: 1,8 a 4,3 UF/mes = .000 a .000/mes para F29, Previred y Renta). Un contador interno indefinido costaría ,8M a ,2M/año (Robert Half / Indeed 2024-2026), inviable para 200 u/año (3-4 h/mes de trabajo real). Sube en Años 3-5 por patente municipal comercial del taller físico.
B13: Materiales indirectos y seguros | C13: 420000 | D13: 480000 | E13: 840000 | F13: 900000 | G13: 980000 | H13: Escala con el volumen y con el activo asegurado
B14: SUBTOTAL GASTOS DE ADMINISTRACIÓN | C14: =C6+C8+C9+C10+C11+C12+C13 | D14: =D6+D8+D9+D10+D11+D12+D13 | E14: =E6+E8+E9+E10+E11+E12+E13 | F14: =F6+F8+F9+F10+F11+F12+F13 | G14: =G6+G8+G9+G10+G11+G12+G13
B16: GASTOS DE COMERCIALIZACIÓN
B17: Publicidad y promoción — Año 1: pauta digital directa sin agencia; Año 2 en adelante: agencia de marketing | C17: ='ESTADO DE RESULTADOS'!E29 | D17: 7080000 | E17: 10680000 | F17: 12000000 | G17: 14400000 | H17: Año 1: Pauta digital directa en Meta Ads y Google Ads autogestionada por los socios con embudo a WhatsApp (.000/mes = ,2M/año). Año 2 en adelante: Retainer de agencia de marketing externa para escalar a 350-850 u/año (más eficiente que contratar un marketer interno con sueldo cargado de -14 M/año).
B18: SUBTOTAL GASTOS DE COMERCIALIZACIÓN | C18: =C17 | D18: =D17 | E18: =E17 | F18: =F17 | G18: =G17
B20: TOTAL GASTOS FIJOS | C20: =C14+C18 | D20: =D14+D18 | E20: =E14+E18 | F20: =F14+F18 | G20: =G14+G18
B22: INDICADORES DERIVADOS POR AÑO
B23: Unidades planificadas | C23: =PARÁMETROS!C26 | D23: =PARÁMETROS!D26 | E23: =PARÁMETROS!E26 | F23: =PARÁMETROS!F26 | G23: =PARÁMETROS!G26 | H23: XI.1
B24: CAC — costo de adquisición por cliente (marketing ÷ unidades) | C24: =C18/C23 | D24: =D18/D23 | E24: =E18/E23 | F24: =F18/F23 | G24: =G18/G23 | H24: El del Año 1 es artificialmente bajo: es trabajo directo de los socios, no una eficiencia replicable
B25: Costo variable unitario | C25: ='COSTOS UNITARIOS'!E29 | D25: ='COSTOS UNITARIOS'!E30 | E25: ='COSTOS UNITARIOS'!E31 | F25: ='COSTOS UNITARIOS'!E32 | G25: ='COSTOS UNITARIOS'!E33 | H25: Curva de escala de XII.2.3
B26: Margen de contribución unitario | C26: =PARÁMETROS!$C$17-C25 | D26: =PARÁMETROS!$C$17-D25 | E26: =PARÁMETROS!$C$17-E25 | F26: =PARÁMETROS!$C$17-F25 | G26: =PARÁMETROS!$C$17-G25 | H26: Precio neto − costo variable unitario
B27: Depreciación anual | C27: =DEPRECIACIÓN!$E$23 | D27: =DEPRECIACIÓN!$E$23 | E27: =DEPRECIACIÓN!$E$23 | F27: =DEPRECIACIÓN!$E$23 | G27: =DEPRECIACIÓN!$E$23 | H27: Constante durante los 5 años
B28: Costo financiero del año | C28: =AMORTIZACIÓN!C30 | D28: =AMORTIZACIÓN!D30 | E28: =AMORTIZACIÓN!E30 | F28: =AMORTIZACIÓN!F30 | G28: =AMORTIZACIÓN!G30 | H28: Intereses de ambos préstamos
B29: PUNTO DE EQUILIBRIO CONTABLE (unidades) | C29: =ROUND((C20+C27+C28)/C26,0) | D29: =ROUND((D20+D27+D28)/D26,0) | E29: =ROUND((E20+E27+E28)/E26,0) | F29: =ROUND((F20+F27+F28)/F26,0) | G29: =ROUND((G20+G27+G28)/G26,0) | H29: Incluye depreciación e interés, no sólo el gasto fijo de caja
B30: Holgura del volumen sobre el equilibrio | C30: =C23/C29-1 | D30: =D23/D29-1 | E30: =E23/E29-1 | F30: =F23/F29-1 | G30: =G23/G29-1 | H30: El Año 3 es el más ajustado: se contrata al segundo ensamblador y se arrienda el primer taller
B32: Por qué las ventas crecen: Año 2, primera agencia de marketing y canal PRODESAL/INDAP; Año 3, convenio con distribuidor de insumos agrícolas y primer taller arrendado; Año 4, consolidación del canal B2B y primera postulación a compra institucional; Año 5, cobertura multirregional con ~1.700 equipos instalados.

Sheet PROYECCIÓN
B2: CUADRO N° 3 — ESTADO DE RESULTADOS PROYECTADO A 5 AÑOS
B3: Álvaro Villena · README XII.5 y XII.7 · Flujo de fondos, VAN, TIR y Pay Back
B5: Concepto | C5: AÑO 0 | D5: AÑO 1 | E5: AÑO 2 | F5: AÑO 3 | G5: AÑO 4 | H5: AÑO 5
B6: Año calendario | C6: 2026 | D6: 2027 | E6: 2028 | F6: 2029 | G6: 2030 | H6: 2031
B7: n (período de descuento) | C7: 0 | D7: 1 | E7: 2 | F7: 3 | G7: 4 | H7: 5
B8: Unidades vendidas | D8: =PARÁMETROS!C26 | E8: =PARÁMETROS!D26 | F8: =PARÁMETROS!E26 | G8: =PARÁMETROS!F26 | H8: =PARÁMETROS!G26
B9: (+) VENTAS | C9: 0 | D9: =D8*PARÁMETROS!$C$17 | E9: =E8*PARÁMETROS!$C$17 | F9: =F8*PARÁMETROS!$C$17 | G9: =G8*PARÁMETROS!$C$17 | H9: =H8*PARÁMETROS!$C$17
B10: (−) COSTOS OPERACIONALES (variables) | C10: 0 | D10: =D8*'COSTOS UNITARIOS'!$E$29 | E10: =E8*'COSTOS UNITARIOS'!$E$30 | F10: =F8*'COSTOS UNITARIOS'!$E$31 | G10: =G8*'COSTOS UNITARIOS'!$E$32 | H10: =H8*'COSTOS UNITARIOS'!$E$33
B11: (−) GASTOS DE ADMINISTRACIÓN | C11: 0 | D11: ='GASTOS FIJOS 5 AÑOS'!C14 | E11: ='GASTOS FIJOS 5 AÑOS'!D14 | F11: ='GASTOS FIJOS 5 AÑOS'!E14 | G11: ='GASTOS FIJOS 5 AÑOS'!F14 | H11: ='GASTOS FIJOS 5 AÑOS'!G14
B12: (−) GASTOS DE COMERCIALIZACIÓN | C12: 0 | D12: ='GASTOS FIJOS 5 AÑOS'!C18 | E12: ='GASTOS FIJOS 5 AÑOS'!D18 | F12: ='GASTOS FIJOS 5 AÑOS'!E18 | G12: ='GASTOS FIJOS 5 AÑOS'!F18 | H12: ='GASTOS FIJOS 5 AÑOS'!G18
B13: (−) DEPRECIACIÓN | C13: 0 | D13: =DEPRECIACIÓN!$E$23 | E13: =DEPRECIACIÓN!$E$23 | F13: =DEPRECIACIÓN!$E$23 | G13: =DEPRECIACIÓN!$E$23 | H13: =DEPRECIACIÓN!$E$23
B14: (−) COSTO FINANCIERO | C14: 0 | D14: =AMORTIZACIÓN!C30 | E14: =AMORTIZACIÓN!D30 | F14: =AMORTIZACIÓN!E30 | G14: =AMORTIZACIÓN!F30 | H14: =AMORTIZACIÓN!G30
B15: (=) UTILIDAD (PÉRDIDA) OPERACIONAL | C15: 0 | D15: =D9-D10-D11-D12-D13-D14 | E15: =E9-E10-E11-E12-E13-E14 | F15: =F9-F10-F11-F12-F13-F14 | G15: =G9-G10-G11-G12-G13-G14 | H15: =H9-H10-H11-H12-H13-H14
B16: (−) IMPUESTO A LA RENTA (25 %) | C16: 0 | D16: =D15*PARÁMETROS!$C$8 | E16: =E15*PARÁMETROS!$C$8 | F16: =F15*PARÁMETROS!$C$8 | G16: =G15*PARÁMETROS!$C$8 | H16: =H15*PARÁMETROS!$C$8
B17: (=) UTILIDAD (PÉRDIDA) NETA DEL PROYECTO | C17: 0 | D17: =D15-D16 | E17: =E15-E16 | F17: =F15-F16 | G17: =G15-G16 | H17: =H15-H16
B19: CÁLCULO DEL FLUJO DE FONDOS PARA LA EVALUACIÓN DEL PROYECTO
B20: Concepto | C20: AÑO 0 | D20: AÑO 1 | E20: AÑO 2 | F20: AÑO 3 | G20: AÑO 4 | H20: AÑO 5
B21: UTILIDAD (PÉRDIDA) NETA DEL PROYECTO | D21: =D17 | E21: =E17 | F21: =F17 | G21: =G17 | H21: =H17
B22: (+) DEPRECIACIÓN — no es salida de caja | D22: =D13 | E22: =E13 | F22: =F13 | G22: =G13 | H22: =H13
B23: (−) CUOTA DE CAPITAL DE LOS PRÉSTAMOS | D23: =AMORTIZACIÓN!C31 | E23: =AMORTIZACIÓN!D31 | F23: =AMORTIZACIÓN!E31 | G23: =AMORTIZACIÓN!F31 | H23: =AMORTIZACIÓN!G31
B24: (−) INVERSIÓN INICIAL | C24: =-INVERSIONES!C45
B25: (=) FLUJO DE FONDOS PROYECTADO | C25: =C24 | D25: =D21+D22-D23 | E25: =E21+E22-E23 | F25: =F21+F22-F23 | G25: =G21+G22-G23 | H25: =H21+H22-H23
B26: FLUJO ACUMULADO | C26: =C25 | D26: =C26+D25 | E26: =D26+E25 | F26: =E26+F25 | G26: =F26+G25 | H26: =G26+H25
B27: El Año 1 es el único con flujo negativo, y es un resultado esperado: la utilidad neta es positiva, pero ese mismo año hay que devolver de golpe la línea de corto plazo completa más la primera cuota del crédito largo. El capital de trabajo está dimensionado para absorberlo.
B29: EVALUACIÓN ECONÓMICA — VALOR ACTUAL NETO (VAN) Y TASA INTERNA DE RETORNO (TIR)
B30: Tasa de rentabilidad exigida (descuento) r = | C30: =PARÁMETROS!C10
B31: Inversión inicial I₀ = | C31: =INVERSIONES!C45
B32: Factor de descuento (1 + r)ⁿ | D32: =(1+$C$30)^D7 | E32: =(1+$C$30)^E7 | F32: =(1+$C$30)^F7 | G32: =(1+$C$30)^G7 | H32: =(1+$C$30)^H7
B33: Valor presente de los flujos proyectados | D33: =D25/D32 | E33: =E25/E32 | F33: =F25/F32 | G33: =G25/G32 | H33: =H25/H32
B34: Sumatoria del valor presente de los flujos (Años 1 a 5) | C34: =SUM(D33:H33)
B35: V. A. N. = Σ VP − I₀ | C35: =C34-C31
B36: V. A. N. — comprobación con la función NPV/VNA | C36: =NPV(C30,D25:H25)+C25
B37: T. I. R. — tasa que anula el VAN | C37: =IRR(C25:H25) | D37: =IF(C37>C30,"✔ La TIR supera la tasa exigida","✘ La TIR es positiva pero no alcanza el 20 % exigido a 5 años")
B39: PAY BACK — PLAZO DE RECUPERACIÓN DE LA INVERSIÓN
B40: Años completos con flujo acumulado todavía negativo | C40: =COUNTIF(D26:H26,"<0")
B41: PAY BACK (años) | C41: =C40+ABS(INDEX(D26:H26,C40))/INDEX(D25:H25,C40+1) | D41: =INT(C41)&" años y "&ROUND((C41-INT(C41))*12,0)&" meses"
B42: Veredicto del Pay Back frente al horizonte de evaluación | C42: =IF(C41<=PARÁMETROS!C12,"✔ Se recupera dentro del horizonte de 5 años, pero al límite","✘ Queda fuera del horizonte de 5 años")
B44: RESUMEN DE INDICADORES
B45: Indicador | C45: Valor | D45: Criterio de aceptación | E45: Veredicto
B46: V. A. N. (20 %) | C46: =C35 | D46: VAN > 0 → el proyecto crea valor | E46: =IF(C35>0,"✔ Cumple","✘ No cumple a 5 años")
...

Sheet SENSIBILIDAD
B2: ANÁLISIS DE SENSIBILIDAD Y PUNTO DE QUIEBRE
B3: README XII.8 · Todo el bloque recalcula la Utilidad Operacional del Año 1 al mover volumen, costo variable y gasto fijo
B4: 1. ESCENARIOS SOBRE EL AÑO 1
B5: Escenario | C5: Δ Volumen | D5: Unidades | E5: Δ Costo variable | F5: Δ Gasto fijo | G5: Utilidad operacional Año 1 | H5: Punto de equilibrio (u) | I5: Lectura
B6: BASE — 200 u a $249.990 con IVA | C6: 0 | D6: =ROUND(PARÁMETROS!$C$26*(1+C6),0) | E6: 0 | F6: 0 | G6: =D6*PARÁMETROS!$C$17-D6*'COSTOS UNITARIOS'!$D$24*(1+E6)-'GASTOS FIJOS 5 AÑOS'!$C$20*(1+F6)-DEPRECIACIÓN!$E$23-AMORTIZACIÓN!$C$30 | H6: =ROUND(('GASTOS FIJOS 5 AÑOS'!$C$20*(1+F6)+DEPRECIACIÓN!$E$23+AMORTIZACIÓN!$C$30)/(PARÁMETROS!$C$17-'COSTOS UNITARIOS'!$D$24*(1+E6)),0) | I6: =IF(G6>1000000,"✅ Utilidad holgada",IF(G6>=0,"⚠ En el umbral de equilibrio","❌ Pérdida en el Año 1"))
B7: Volumen −10 % | C7: -0.1 | D7: =ROUND(PARÁMETROS!$C$26*(1+C7),0) | E7: 0 | F7: 0 | G7: =D7*PARÁMETROS!$C$17-D7*'COSTOS UNITARIOS'!$D$24*(1+E7)-'GASTOS FIJOS 5 AÑOS'!$C$20*(1+F7)-DEPRECIACIÓN!$E$23-AMORTIZACIÓN!$C$30 | H7: =ROUND(('GASTOS FIJOS 5 AÑOS'!$C$20*(1+F7)+DEPRECIACIÓN!$E$23+AMORTIZACIÓN!$C$30)/(PARÁMETROS!$C$17-'COSTOS UNITARIOS'!$D$24*(1+E7)),0) | I7: =IF(G7>1000000,"✅ Utilidad holgada",IF(G7>=0,"⚠ En el umbral de equilibrio","❌ Pérdida en el Año 1"))
B8: Volumen −17 % (umbral de equilibrio) | C8: -0.17 | D8: =ROUND(PARÁMETROS!$C$26*(1+C8),0) | E8: 0 | F8: 0 | G8: =D8*PARÁMETROS!$C$17-D8*'COSTOS UNITARIOS'!$D$24*(1+E8)-'GASTOS FIJOS 5 AÑOS'!$C$20*(1+F8)-DEPRECIACIÓN!$E$23-AMORTIZACIÓN!$C$30 | H8: =ROUND(('GASTOS FIJOS 5 AÑOS'!$C$20*(1+F8)+DEPRECIACIÓN!$E$23+AMORTIZACIÓN!$C$30)/(PARÁMETROS!$C$17-'COSTOS UNITARIOS'!$D$24*(1+E8)),0) | I8: =IF(G8>1000000,"✅ Utilidad holgada",IF(G8>=0,"⚠ En el umbral de equilibrio","❌ Pérdida en el Año 1"))
B9: Volumen −20 % | C9: -0.2 | D9: =ROUND(PARÁMETROS!$C$26*(1+C9),0) | E9: 0 | F9: 0 | G9: =D9*PARÁMETROS!$C$17-D9*'COSTOS UNITARIOS'!$D$24*(1+E9)-'GASTOS FIJOS 5 AÑOS'!$C$20*(1+F9)-DEPRECIACIÓN!$E$23-AMORTIZACIÓN!$C$30 | H9: =ROUND(('GASTOS FIJOS 5 AÑOS'!$C$20*(1+F9)+DEPRECIACIÓN!$E$23+AMORTIZACIÓN!$C$30)/(PARÁMETROS!$C$17-'COSTOS UNITARIOS'!$D$24*(1+E9)),0) | I9: =IF(G9>1000000,"✅ Utilidad holgada",IF(G9>=0,"⚠ En el umbral de equilibrio","❌ Pérdida en el Año 1"))
B10: Costo variable +15 % | C10: 0 | D10: =ROUND(PARÁMETROS!$C$26*(1+C10),0) | E10: 0.15 | F10: 0 | G10: =D10*PARÁMETROS!$C$17-D10*'COSTOS UNITARIOS'!$D$24*(1+E10)-'GASTOS FIJOS 5 AÑOS'!$C$20*(1+F10)-DEPRECIACIÓN!$E$23-AMORTIZACIÓN!$C$30 | H10: =ROUND(('GASTOS FIJOS 5 AÑOS'!$C$20*(1+F10)+DEPRECIACIÓN!$E$23+AMORTIZACIÓN!$C$30)/(PARÁMETROS!$C$17-'COSTOS UNITARIOS'!$D$24*(1+E10)),0) | I10: =IF(G10>1000000,"✅ Utilidad holgada",IF(G10>=0,"⚠ En el umbral de equilibrio","❌ Pérdida en el Año 1"))
B11: Gastos fijos +15 % | C11: 0 | D11: =ROUND(PARÁMETROS!$C$26*(1+C11),0) | E11: 0 | F11: 0.15 | G11: =D11*PARÁMETROS!$C$17-D11*'COSTOS UNITARIOS'!$D$24*(1+E11)-'GASTOS FIJOS 5 AÑOS'!$C$20*(1+F11)-DEPRECIACIÓN!$E$23-AMORTIZACIÓN!$C$30 | H11: =ROUND(('GASTOS FIJOS 5 AÑOS'!$C$20*(1+F11)+DEPRECIACIÓN!$E$23+AMORTIZACIÓN!$C$30)/(PARÁMETROS!$C$17-'COSTOS UNITARIOS'!$D$24*(1+E11)),0) | I11: =IF(G11>1000000,"✅ Utilidad holgada",IF(G11>=0,"⚠ En el umbral de equilibrio","❌ Pérdida en el Año 1"))
B12: PESIMISTA combinado (−10 % vol, +15 % CV, +15 % GF) | C12: -0.1 | D12: =ROUND(PARÁMETROS!$C$26*(1+C12),0) | E12: 0.15 | F12: 0.15 | G12: =D12*PARÁMETROS!$C$17-D12*'COSTOS UNITARIOS'!$D$24*(1+E12)-'GASTOS FIJOS 5 AÑOS'!$C$20*(1+F12)-DEPRECIACIÓN!$E$23-AMORTIZACIÓN!$C$30 | H12: =ROUND(('GASTOS FIJOS 5 AÑOS'!$C$20*(1+F12)+DEPRECIACIÓN!$E$23+AMORTIZACIÓN!$C$30)/(PARÁMETROS!$C$17-'COSTOS UNITARIOS'!$D$24*(1+E12)),0) | I12: =IF(G12>1000000,"✅ Utilidad holgada",IF(G12>=0,"⚠ En el umbral de equilibrio","❌ Pérdida en el Año 1"))
B14: 2. HOLGURA DISPONIBLE ANTES DEL QUIEBRE
B15: Variable | C15: Holgura | I15: Lectura
B16: Volumen de ventas | C16: −17 % (166 u) | I16: El proyecto tolera vender bastante menos de lo planificado antes de perder en el Año 1 — mejor que el estudio anterior (−10 %), porque el volumen base ya es más alto
B17: Costo variable unitario | C17: +15 % aprox. | I17: Ajustado. Un alza del dólar o de los precios de LCSC por sobre ese margen compromete el Año 1
B18: Gastos fijos | C18: +15 % aprox. | I18: Ajustado. Poco margen para adelantar contrataciones o subir sueldos más rápido de lo planificado
B19: Precio de venta | C19: Sin holgura | I19: No hay palanca de precio disponible: $249.990 con IVA es el techo declarado del negocio y ya está en uso
B21: 3. SENSIBILIDAD DEL VAN A LA TASA DE DESCUENTO
B22: Tasa de descuento | C22: V. A. N. | I22: Lectura
B23: 0.05 | C23: =NPV(B23,PROYECCIÓN!$D$25:$H$25)+PROYECCIÓN!$C$25 | I23: =IF(C23>0,"VAN positivo: a esta exigencia el proyecto se paga en 5 años","VAN negativo: a esta exigencia no se paga en 5 años")
B24: 0.08 | C24: =NPV(B24,PROYECCIÓN!$D$25:$H$25)+PROYECCIÓN!$C$25 | I24: =IF(C24>0,"VAN positivo: a esta exigencia el proyecto se paga en 5 años","VAN negativo: a esta exigencia no se paga en 5 años")
B25: 0.085 | C25: =NPV(B25,PROYECCIÓN!$D$25:$H$25)+PROYECCIÓN!$C$25 | I25: =IF(C25>0,"VAN positivo: a esta exigencia el proyecto se paga en 5 años","VAN negativo: a esta exigencia no se paga en 5 años")
B26: 0.09 | C26: =NPV(B26,PROYECCIÓN!$D$25:$H$25)+PROYECCIÓN!$C$25 | I26: =IF(C26>0,"VAN positivo: a esta exigencia el proyecto se paga en 5 años","VAN negativo: a esta exigencia no se paga en 5 años")
B27: 0.1 | C27: =NPV(B27,PROYECCIÓN!$D$25:$H$25)+PROYECCIÓN!$C$25 | I27: =IF(C27>0,"VAN positivo: a esta exigencia el proyecto se paga en 5 años","VAN negativo: a esta exigencia no se paga en 5 años")
B28: 0.15 | C28: =NPV(B28,PROYECCIÓN!$D$25:$H$25)+PROYECCIÓN!$C$25 | I28: =IF(C28>0,"VAN positivo: a esta exigencia el proyecto se paga en 5 años","VAN negativo: a esta exigencia no se paga en 5 años")
B29: 0.2 | C29: =NPV(B29,PROYECCIÓN!$D$25:$H$25)+PROYECCIÓN!$C$25 | I29: =IF(C29>0,"VAN positivo: a esta exigencia el proyecto se paga en 5 años","VAN negativo: a esta exigencia no se paga en 5 años")
B30: TIR del proyecto (donde el VAN se anula) | C30: =PROYECCIÓN!C37
B32: Conclusión: el escenario base tolera peor los desvíos de costo o de gasto fijo que el estudio anterior, pero tolera mejor los desvíos de volumen porque el volumen base subió. La diferencia clave es que ya no queda margen de precio: la única palanca de ajuste real frente a un mal Año 1 es el volumen, y de ahí que toda la estrategia comercial del Año 1 esté orientada a protegerlo.

Sheet TOMA DE DECISIONES
B2: TOMA DE DECISIONES DEL PROYECTO
B3: Álvaro Villena · README XII.10 · Decisión fundamentada en el VAN y la TIR, y decisión fundamentada en el Pay Back
B5: RESPUESTA 1 — DECISIÓN EN BASE AL VAN Y A LA TIR
B6: RESPUESTA 1 — TOMA DE DECISIONES EN BASE AL VAN Y A LA TIR DECISIÓN: SE ACEPTA EL PROYECTO. CUMPLE EL CRITERIO ESTÁNDAR DE 5 AÑOS Y 20 %. El Valor Actual Neto calculado con la tasa de rentabilidad exigida del 20 % es POSITIVO: $2.588.182. La TIR real del proyecto es de aproximadamente 22,7 %, superando la tasa exigida del 20 %. Bajo el criterio estricto de la planilla estándar de evaluación —VAN > 0 y TIR > 20 % a cinco años— este proyecto SE ACEPTA sin necesidad de apelar a un horizonte más largo. Este resultado es distinto del de la versión anterior del modelo (VAN negativo, −$8.143.581) porque se revisaron tres supuestos que antes eran demasiado conservadores o estaban incompletos, no porque se haya suavizado ninguna de las tres condiciones de fondo (sonda a precio real, sueldo de ambos socios desde el mes 1, techo de precio de $249.990): 1) Se incorporó un 10 % de contingencia/imprevistos sobre la inversión inicial (+$2.413.500) y se desglosaron uno a uno los gastos reales de constituir la empresa (INAPI, patente municipal, firma electrónica, honorarios contables de puesta en marcha), lo que en realidad ENCARECE la inversión inicial a $26.548.500. Este cambio por sí solo empeora el VAN: es más prudente, no más optimista. 2) Se revisó la tasa de la línea de corto plazo de 23 % a 15 % anual: el monto del crédito (~$5.000.000) es pequeño y el proyecto ya tiene garantía FOGAPE en el crédito de largo plazo, por lo que un banco no tendría motivo para negarla ni cobrarla como una línea de consumo sin garantía. Esto reduce el costo financiero de todos los años. 3) Se redimensionó la dotación de ensambladores contratados según las horas reales de trabajo (ensamblaje + QA + testing + embalaje, 2,25 h/unidad sobre 1.800 h productivas por FTE al año), en vez de una dotación creciente sin ese respaldo. El resultado es 0,5 FTE el Año 2, 1 FTE los Años 3 y 4, y 1,5 FTE el Año 5 — bastante menos que el escenario anterior (1, 2, 3 y 4 personas) y un ahorro acumulado de gasto fijo relevante en el quinquenio. El efecto neto de las tres correcciones es positivo: el ahorro en gasto fijo (ensambladores) y en costo financiero (tasa corta) supera con holgura el mayor desembolso inicial de la contingencia y de los gastos de constitución desglosados. La utilidad neta es POSITIVA todos los años, sin excepción, desde el Año 1: crece de $2.985.381 a $32.714.084 entre el Año 1 y el Año 5. El único año con flujo de caja negativo —el Año 1— lo sigue siendo, por la misma razón que antes: ese año se devuelve íntegra la línea de corto plazo, desembolso que el capital de trabajo está dimensionado para absorber. Se deja expresamente registrado que este resultado depende de que la tasa de la línea de corto plazo se confirme en terreno (cotizar con 2-3 bancos PYME antes de firmar) y de que la reducción de dotación de ensambladores sea efectivamente viable en la operación; ambos supuestos son razonables pero no están garantizados hasta la ejecución real.
B8: RESPUESTA 2 — DECISIÓN EN BASE AL PAY BACK
B9: RESPUESTA 2 — TOMA DE DECISIONES EN BASE AL PAY BACK DECISIÓN: SE ACEPTA, CON HOLGURA RAZONABLE. El período de recuperación de la inversión es de 3,71 años —tres años y nueve meses— sobre un horizonte de evaluación de cinco años. El flujo acumulado parte en −$26.548.500 el Año 0, sigue negativo durante los Años 1 a 3 y cruza a positivo dentro del Año 4, cerrando el quinquenio en $36.168.514. CRITERIO DE DECISIÓN: mientras menor sea el plazo de recuperación, menor es el riesgo y más líquido es el proyecto. Un Pay Back de 3,71 años cae dentro del horizonte exigido y con más margen que en la versión anterior del modelo (que recuperaba recién en 4,42 años, casi al límite del quinquenio). El Año 1 es el único con flujo de fondos negativo (−$3.275.221) y eso no es una señal de alarma: la utilidad neta de ese año es positiva ($2.985.381), y el flujo se vuelve negativo únicamente porque hay que pagar de golpe $7.071.792 de capital (línea de corto plazo completa más la primera cuota del crédito de largo plazo, ahora algo mayor porque el crédito de largo plazo también financia la contingencia). El capital de trabajo de la inversión inicial está dimensionado para absorber ese desembolso. CONCLUSIÓN: el Pay Back confirma la decisión tomada en base al VAN y la TIR. La evaluación a 5 años y 20 % —la vara más exigente que este proyecto puede pasar— ya no se pasa al límite, sino con margen: los tres ajustes (contingencia real, tasa de línea corta revisada y dotación de ensambladores dimensionada por horas) mueven el proyecto de 'se acepta condicionado a un horizonte más largo' a 'se acepta bajo el criterio estándar de la planilla'.
B11: DECISIÓN CONJUNTA — RESUMEN DE CRITERIOS
B12: Criterio | C12: Resultado | D12: Umbral (5 años, 20 %) | E12: Decisión
B13: V. A. N. (20 %) | C13: =PROYECCIÓN!C35 | D13: > 0 | E13: =IF(PROYECCIÓN!C35>0,"✔ Cumple","✘ No cumple")
B14: T. I. R. | C14: =PROYECCIÓN!C37 | D14: > 20 % | E14: =IF(PROYECCIÓN!C37>PROYECCIÓN!C30,"✔ Cumple","✘ No cumple, pero es positiva")
B15: Pay Back | C15: =PROYECCIÓN!C41 | D15: ≤ 5 años | E15: =IF(PROYECCIÓN!C41<=5,"✔ Cumple, sin holgura","✘ No cumple")
B16: Utilidad neta de todos los años | C16: =IF(MIN(PROYECCIÓN!D17:H17)>0,"Positiva","Con pérdidas") | D16: Sin pérdidas | E16: =IF(MIN(PROYECCIÓN!D17:H17)>0,"✔ Cumple","✘ No cumple")
B17: Punto de equilibrio del Año 1 | C17: ='GASTOS FIJOS 5 AÑOS'!C29 | D17: < 200 u planificadas | E17: =IF('GASTOS FIJOS 5 AÑOS'!C29<'GASTOS FIJOS 5 AÑOS'!C23,"✔ Cumple","✘ No cumple")
B19: Los cinco criterios de evaluación se cumplen: VAN positivo, TIR sobre el 20 % exigido, Pay Back dentro del horizonte, utilidad neta positiva todos los años y punto de equilibrio del Año 1 por debajo de las 200 unidades planificadas. La recomendación de este estudio es aceptar el proyecto bajo el criterio estándar de 5 años y 20 %, con dos condiciones de verificación real antes de firmar: (1) confirmar con 2-3 bancos que la línea de corto plazo efectivamente se puede obtener cerca del 15 % anual con garantía FOGAPE, y (2) validar operativamente que la dotación reducida de ensambladores (0,5 a 1,5 FTE según el año) es suficiente en la práctica.

Sheet RÚBRICA
B2: RÚBRICA — EVALUACIÓN ECONÓMICA DEL PROYECTO FINAL
B3: Preparación y Evaluación de Proyectos · ES3 Evaluación económica del proyecto final
B5: PUNTOS | C5: MUY BUENO 100 % | D5: BUENO 60 % | E5: REGULAR 50 % | F5: INSUFICIENTE 10 %
B6: 20 | C6: Presenta la INVERSIÓN INICIAL del proyecto bien clasificada, con las fuentes de financiamiento. Cálculo de la DEPRECIACIÓN ANUAL y de la AMORTIZACIÓN del capital y los intereses. | D6: Presenta de acuerdo a la planilla Excel solicitada, completo, pero con errores de clasificación y de cálculo. | E6: Se presenta de acuerdo a la planilla Excel solicitada, incompleto y mal clasificado, con muchos errores de cálculo. | F6: No utiliza la planilla Excel solicitada; errores de clasificación y de cálculo. Incompleta.
C7: 20 | D7: 12 | E7: 10 | F7: 2
B8: 20 | C8: Presenta el ESTADO DE RESULTADOS con los conceptos bien clasificados y bien calculados. | D8: Presenta de acuerdo a la planilla Excel solicitada, completo, pero con errores de clasificación y de cálculo. | E8: Se presenta de acuerdo a la planilla Excel solicitada, incompleto y mal clasificado, con muchos errores de cálculo. | F8: No utiliza la planilla Excel solicitada; errores de clasificación y de cálculo. Incompleta.
C9: 20 | D9: 12 | E9: 10 | F9: 2
B10: 20 | C10: Presenta el Excel de PROYECCIÓN A CINCO AÑOS, completa, bien clasificada y sin errores de cálculo. | D10: Presenta de acuerdo a la planilla Excel solicitada, completo, pero con errores de clasificación y de cálculo. | E10: Se presenta de acuerdo a la planilla Excel solicitada, incompleto y mal clasificado, con muchos errores de cálculo. | F10: No utiliza la planilla Excel solicitada; errores de clasificación y de cálculo. Incompleta.
C11: 20 | D11: 12 | E11: 10 | F11: 2
B12: 10 | C12: Calcula el VAN y el PAY BACK sin errores de cálculo. | D12: Presenta errores de cálculo por clasificaciones y cifras. Presenta VAN y Pay Back. | E12: Presenta errores de cálculo. No presenta uno de los instrumentos de evaluación económica. | F12: Presenta errores de cálculo. No presenta dos de los instrumentos de evaluación económica.
C13: 10 | D13: 6 | E13: 5 | F13: 1
B14: 30 | C14: TOMA DE DECISIONES del proyecto: 1) en base al VAN y 2) en base al Pay Back. Completa y con argumentos robustos y sólidos, justificando la respuesta. | D14: La toma de decisiones se presenta completa, pero con argumentos débiles. | E14: La toma de decisiones se presenta corta e incompleta, con argumentos débiles y sin justificación. | F14: Toma de decisiones incompleta, sin detalle y débil.
C15: 30 | D15: 18 | E15: 15 | F15: 3
B16: =SUM(B6,B8,B10,B12,B14) | C16: =SUM(C7,C9,C11,C13,C15) | D16: =SUM(D7,D9,D11,D13,D15) | E16: =SUM(E7,E9,E11,E13,E15) | F16: =SUM(F7,F9,F11,F13,F15)
C18: INSTRUCCIONES DE ENTREGA
C19: • Todo se entrega en la planilla Excel de respuestas subida al AAI.
C20: • Todos los cálculos se deben hacer dentro de la planilla Excel de respuestas.
C21: • El Excel de respuestas se presenta con el nombre de todos los integrantes del equipo de trabajo.
